Workbook

Sheet Overview
A1: co | C1: WarrantyFirst Customer Stories
B2: Service | C2: Customer Story | D2: Suggested Path | E2: Assumptions | F2: Estimated Low Hours | G2: Estimated High Hours | H2: Potential Variance | I2: Function | J2: POC
B4: Executive Summary | E4: Additional Notes + Considerations
B5: Warranty First provides car, van, and bike protection direct to customers and through a network of dealers. The Warranty First team has been using various tools to manage relationships with their clients and dealers via CRM related activities and portals to make it easy for their end users to interact with them. Recently, it's become apparent that there are some challenges within their current stack and the team has been exploring different options to unify these activities to streamline and standardize processes across the org. A true digital transformation journey. HubSpot became a strong contender due to its ease of use and customizable capabilities that will allow Warranty First and their GTM teams to operate under one umbrella. By leveraging sales, marketing, and custom portal offerings within HubSpot, the Warranty First team will be able to streamline and automate sales efforts, dealer portal interactions, and claim management processes. Warranty First requires a scalable data architecture that allows them to manage and standardize sales and marketing activities in one place. A comprehensive approach to data quality, process management, and automation is necessary.
A7: • | B7: Requirements + Solutioning Workshops | F7: =IFERROR(__xludf.DUMMYFUNCTION("ROUNDUP( ( SUM( INDIRECT( ""F""&(ROW()+1)&"":F""& IFERROR( INDEX( FILTER( ROW(A:A), REGEXMATCH(A:A, ""^[•◆■※⊳]""), ROW(A:A) > ROW() ), 1 "&" )-1, 999 ) ) )+ SUM( INDIRECT( ""G""&(ROW()+1)&"":G""& IFERROR( INDEX( FILTER( ROW(A:A), REGEXMATCH(A:A, ""^[•◆■※⊳]""), ROW(A:A) "&"> ROW() ), 1 )-1, 999 ) ) ) )/2 )"),150.0) -> 150 | H7: Standard
B8: Requirements Gathering | C8: WarrantyFirst's business objective is to create a cohesive business data, systems, process, and people roadmap that addresses their ideal future state, supports growth and adapts to evolving business needs. | D8: Conduct Discovery and Requirements Gathering Sessions & Produce a summary recommendations document including a detailed documentation of the current state as well as the future state business and technical requirements, including comprehensive diagrams detailing data model, process, integrations, and reporting details. | E8: - Aptitude 8 will prioritize the following workstreams: marketing, sales, operations, data, and integrations. | F8: 35 | G8: 35
B9: Data Model & Systems Architecture Strategy | C9: Warranty First needs to define a HubSpot data model that reflects their business in order to run sales processes and servicing proceses effectively at scale. | D9: Aptitude 8 should run a data modeling exercise to finalize objects, relationships, and properties for migration purposes and for future growth. They should also identify which objects map between which systems. | E9: - Aptitude 8 will create an ERD that defines object definitions, associations and association types, and up to 5 key properties. - Aptitude 8 will create data migration diagram to show how existing data maps to HubSpot - Aptitude 8 will create a basic visual to demonstrate how data flows between systems: what data maps and in what direction - Aptitude 8 will ensure the correct field level permissions are finalized before creating all fields | F9: 20 | G9: 20
B10: Proof of Concept/Solutioning | C10: WarrantyFirst desires a collaborative engagement to solve for key business and technical requirements. | D10: Plan workshops to solve for key workstreams, discuss options, and decide on a path forward. | E10: - Aptitude 8 will guide WarrantyFirst through a series of workshops that help them understand how they can solve for business and technical requirements. - Aptitude 8 might use hours in this line item to build proof of concept's to demonstrate how different options will look and function. | F10: 60 | G10: 60
B11: Portal Migration Strategy | C11: Warranty First needs to migrate current users to HubSpot so they can access the new portal(s). | D11: Aptitude 8 should recommend a plan that highlights the WHAT, HOW, and WHEN to migrate users to the new portals. | E11: - Up to 10 advisory hours to assist the WarrantyFirst team - Aptitude 8 will not manage any communications such as emails, SMS, or calls, nor automations required to complete the transition. Example: Aptitude 8 will not setup emails to inform current planholders or dealer contacts of the move to HubSpot's customer portal BUT Aptitude 8 will consult on best ways to approach this considering their HubSpot expertise. | F11: 10 | G11: 10
B12: Project Planning | C12: WarrantyFirst desires a roadmap that details what needs to be done by when by who as they migrate the new company into their business. | D12: Create a gantt chart with first and second level dependencies to prepare WarrantyFirst's team for an all hands on deck approach. Finalize project decisions are made in this phase at the latest. | E12: - Aptitude 8 will ensure each workstream has a dedicated owner, milestones are defined, drop dead dates are denoted - Aptitude 8 will create a Gantt chart as source of truth for the project plan for key integrations, marketing and sales processes, and key record and other asset migration | F12: 25 | G12: 25
A14: • | B14: HubSpot Configuration - Data Model, Users, and Permissions | F14: =IFERROR(__xludf.DUMMYFUNCTION("ROUNDUP( ( SUM( INDIRECT( ""F""&(ROW()+1)&"":F""& IFERROR( INDEX( FILTER( ROW(A:A), REGEXMATCH(A:A, ""^[•◆■※⊳]""), ROW(A:A) > ROW() ), 1 "&" )-1, 999 ) ) )+ SUM( INDIRECT( ""G""&(ROW()+1)&"":G""& IFERROR( INDEX( FILTER( ROW(A:A), REGEXMATCH(A:A, ""^[•◆■※⊳]""), ROW(A:A) "&"> ROW() ), 1 )-1, 999 ) ) ) )/2 )"),25.0) -> 25 | H14: Standard
B15: Data Model Build | C15: Warranty First needs to create HubSpot data model that reflects their business in order to run sales processes and servicing processes effectively at scale. | D15: Aptitude 8 should take the output of the Data & Systems Architecture line item (row 7) as technical specs to implement Warranty First's data model. | E15: - Aptitude 8 will create up to 30 custom properties for each standard object WarrantyFirst intends to use. These objects are: Contacts, Companies, Deals, and Tickets. - Aptitude 8 will create up to 6 custom objects: Policies, Claim Items, Cover Levels, Xero Invoices, and Vehicles. Each will include the appropriate associations and association labels - Aptitude 8 will create up to two conditional custom property sections per object. WarrantyFirst must provide the specs for Aptitude 8 to complete. | F15: 20 | G15: 20
B16: Users & Permissions | C16: Warranty First needs to implement permissions and teams for users in HubSpot so the right people can view, edit, and create the correct records in the CRM. | D16: Aptitude 8 should run an efficient user/permission exercise for Warranty First to input requirements into. | E16: - Up to 50 sales users - Up to 10 teams - Up to 10 admin/exec seats and teams required to segment | F16: 5 | G16: 5
A18: • | B18: Data Migration | F18: =IFERROR(__xludf.DUMMYFUNCTION("ROUNDUP( ( SUM( INDIRECT( ""F""&(ROW()+1)&"":F""& IFERROR( INDEX( FILTER( ROW(A:A), REGEXMATCH(A:A, ""^[•◆■※⊳]""), ROW(A:A) > ROW() ), 1 "&" )-1, 999 ) ) )+ SUM( INDIRECT( ""G""&(ROW()+1)&"":G""& IFERROR( INDEX( FILTER( ROW(A:A), REGEXMATCH(A:A, ""^[•◆■※⊳]""), ROW(A:A) "&"> ROW() ), 1 )-1, 999 ) ) ) )/2 )"),50.0) -> 50 | H18: High
B19: CRM Migration | C19: Warranty First needs to migrate historical records into HubSpot in order for business to continue as usual. | D19: Aptitude 8 will advise Warranty First of what format different CSVs should be and import using the HubSpot Import tool. | E19: -WarrantyFirst will provide CSVs formatted per Aptitude 8's direction in order for Aptitude 8 to import into historical records into HubSpot - Aptitude 8 will migrate up to 2,500 dealer (companies) records, 1,000 dealer user (contacts), 48,000 Planholders (contacts), 100,000 policies, 61,000 claims, 21,000 auto body shops (companies), up to 15,000 pricing related tables - Aptitude 8 will not complete any data clean up but does allocate up to 5 of the hours in the line item to recommending how to clean for import and how to strcture the data in the CSVs | F19: 50 | G19: 50
A21: • | B21: HubSpot Implementation - SalesHub | F21: =IFERROR(__xludf.DUMMYFUNCTION("ROUNDUP( ( SUM( INDIRECT( ""F""&(ROW()+1)&"":F""& IFERROR( INDEX( FILTER( ROW(A:A), REGEXMATCH(A:A, ""^[•◆■※⊳]""), ROW(A:A) > ROW() ), 1 "&" )-1, 999 ) ) )+ SUM( INDIRECT( ""G""&(ROW()+1)&"":G""& IFERROR( INDEX( FILTER( ROW(A:A), REGEXMATCH(A:A, ""^[•◆■※⊳]""), ROW(A:A) "&"> ROW() ), 1 )-1, 999 ) ) ) )/2 )"),133.0) -> 133 | H21: Standard
B22: Field Sales Implementation | C22: Warranty First needs to create a new business pipeline so they can track and manage opportunities to sell warranties at new dealerships. | D22: Aptitude 8 should run discovery on sales process in order to configure the foundation for the field sales team. The emphasis should be to simplify and implement a sales process that makes it easy for the team to adopt. | E22: - Aptitude 8 will create one deal pipeline with the appropriate deal stages and required properties - Create one deal pipeline to reflect new policies add by dealerships. This pipeline should have stages such as policy submitted, in approval process, and closed won/lost. A workflow should be created to automatically convert a new policy approved to a deal in closed won in this pipeline. - Aptitude 8 will create up to 3 call & meeting types & as many outcomes needed for those types - Aptitude 8 will ensure all reps on the field sales team have their calendar and emails integrated with HubSpot to automatically track those details in HubSpot - Ability to specify the dealers invoice cycle so Xero knows when to create and send invoices | F22: 18 | G22: 18
B23: Small Dealerships Sales Implementation | C23: Warranty First needs to implement a basic sales process for their small dealerships sales team so they can begin to scale. | D23: Aptitude 8 should run discovery on sales process in order to configure the foundation for the small dealerships team. Aptitude 8 should recommend how to segment this team's process and the Field Sales team's process IF they are different and if they are not, recommend how to filter between the two. The emphasis should be to simplify and implement a sales process that makes it easy for the team to adopt. | E23: - Aptitude 8 will create one deal pipeline with the appropriate deal stages and required properties - Aptitude 8 will create up to 3 call & meeting types & as many outcomes needed for those types - Aptitude 8 will ensure all reps on the field sales team have their calendar and emails integrated with HubSpot to automatically track those details in HubSpot | F23: 15 | G23: 15
B24: Dealer Agreement Template | C24: Warranty First needs to dealerships to sign a partnership agreement in order to sell their warranties. | D24: Aptitude 8 should create a basic quote template with e-sign and approval workflow to send to new dealership partners. This acts as an official step at the end of the Field Sales process. | E24: - Aptitude 8 will create a basic quote template the Field Sales team can use to quickly create, get manager approval, and send to the dealership contact. - This assumes a custom quote template that meets WarrantyFirst's brand requirements and includes e-signature. - No pricing or payment is listed on the quote. | F24: 15 | G24: 15
B25: Xero Integration | C25: Warranty First wants to automatically generate a Xero invoice for the dealership of a newly approved policy. | D25: Aptitude 8 should create a company based workflow and a custom coded action to automatically draft and send Xero Invoices based on the companies (dealerships) billing cycle. The invoice should aggregate (sum) all policies sold within the billing cycle and be sent to the billing contact's email in Xero. | E25: - Aptitude 8 will build a workflow that uses a custom code action to create a Xero Invoice as Authorised via API and then send to the email address on file. - Aptitude 8 assumes no Invoice approval process applies. | F25: 40 | G25: 40
B26: Implement HubSpot Calling | C26: Warranty First seeks to use HubSpot's calling features so they can do basic incoming call routing to the appropriate team members, get call analysis for coaching purposes, and report on the activity accurately. | D26: Consult WarrantyFirst on the limitations, understand their requirements, help them build a v1 and consult the HubSpot product team to roadmap their calling solutions for the future. | E26: - Set up call routing for all reps across all teams. Note: HubSpot limitations apply and therefore WarrantyFirst might not have all requirements met from day 1. Aptitude 8 will make clear what those limitations are and how they translate to the implementation of HubSpot calling. - Training and enablement will be included in the Training line item | F26: 25 | G26: 25
B27: Reporting and Dashboards | C27: Warranty First aims for enhanced reporting capabilities in HubSpot to obtain accurate insights into customer journeys, sales performance, dealer goals, and renewal opportunities. | D27: Aptitude 8 will configure up to (10) custom reports and (3) dashboards for Warranty First sales and claims team. | E27: - Up to 10 custom reports, 2 custom dashboards. - Up to 3 OOTB dashboards with filter only customization to their reports. | F27: 20 | G27: 20
A29: • | B29: B2C Sales Team Process Optimization | F29: =IFERROR(__xludf.DUMMYFUNCTION("ROUNDUP( ( SUM( INDIRECT( ""F""&(ROW()+1)&"":F""& IFERROR( INDEX( FILTER( ROW(A:A), REGEXMATCH(A:A, ""^[•◆■※⊳]""), ROW(A:A) > ROW() ), 1 "&" )-1, 999 ) ) )+ SUM( INDIRECT( ""G""&(ROW()+1)&"":G""& IFERROR( INDEX( FILTER( ROW(A:A), REGEXMATCH(A:A, ""^[•◆■※⊳]""), ROW(A:A) "&"> ROW() ), 1 )-1, 999 ) ) ) )/2 )"),95.0) -> 95 | H29: Low
B30: Auto-Generate Renewal Deal | C30: Warranty First needs to more easily and accurately track renewal deals and seeks for an automation to create and flag them to the appropriate deal owner. | D30: Create a deal based workflow that generates a deal in the renewal pipeline. Aptitude 8 should also consider making recommendations to the Warranty First team on their existing renewal pipeline. However, no changes to the pipeline are in this scope. | E30: - One workflow to create a renewal deal based on when a policy has been approved, when it starts, the policy specs, and associated contact - We assume a renewal pipeline exists today because that team is using HubSpot and therefore, no new pipeline needs to be created. - If changes to the existing pipeline are required, the team can use contingency hours OR submit a change order. | F30: 5 | G30: 5
B31: Create A Quote CRM Card - Renewal | C31: Warranty First needs the ability for their telesales team to build out quotes for customers up for renewal. | D31: Aptitude 8 should lead a structured fireframing and requirements confirmation engagement to finalize the CRM card details such as: where it lives, what infrastructure powers it, what data is required, what the inputs are, what the outputs are | E31: - Ability to run vehicle registration validation to ensure it's a real vehicle and return vehicle details - Ability to create a quote with pricing, legal language, and e-signature. - Aptitude 8 will create a CRM card to intake pricing inputs and create quote draft(s) based on the inputs so the telesales team can send it to customers - Ability to re-quote them for renewal - Ability to pre-populate or update contact information as part of the renewal - Ability to update vehicle information (miles, miles per year, sale price, service history, years owned) - Ability to specify new policy start date - Ability to show plans the customer is eligible for based on above inputs - Ability to toggle between monthly and upfront payments - Ability to save quote to come back to later - Ability for the following payment plans: invoice, assist, monthly, now | F31: 75 | G31: 75
B32: Generate Certificate of Warranty for Planholder | C32: Warranty First needs generate a warranty certificate so planholders can print it out or save electronically. | D32: System today automatically generates this and we will need to replicate it today. | E32: - Aptitude 8 will automatically generate a pdf per WarrantyFirst's design specs in two scenarios: 1) when a renewing customer signs a renewal agreement and 2) when a policy added by a dealer is approved by WarrantyFirst | F32: 15 | G32: 15
A34: • | B34: Self-Serve Checkout Implementation | F34: =IFERROR(__xludf.DUMMYFUNCTION("ROUNDUP( ( SUM( INDIRECT( ""F""&(ROW()+1)&"":F""& IFERROR( INDEX( FILTER( ROW(A:A), REGEXMATCH(A:A, ""^[•◆■※⊳]""), ROW(A:A) > ROW() ), 1 "&" )-1, 999 ) ) )+ SUM( INDIRECT( ""G""&(ROW()+1)&"":G""& IFERROR( INDEX( FILTER( ROW(A:A), REGEXMATCH(A:A, ""^[•◆■※⊳]""), ROW(A:A) "&"> ROW() ), 1 )-1, 999 ) ) ) )/2 )"),60.0) -> 60 | H34: High
B35: Create A Quote - Self Serve | C35: Warranty First needs the ability for people to purchase warranties on their website without sales assistance. | D35: Confirm the inputs, the components of the custom form, the outputs, downstream actions required in order to execute | E35: - Replicating the current create a quote inputs, policy recommendations, and checkout experience with a payments partners is required. - Aptitude 8 assumes payment partners have reliable and stable APIs and if not, a change order will result. - Aptitude 8 will build the self serve widget on HubSpot tools like ContentHub and use it's features to recreate the custom form - Aptitude 8 will consult WarrantyFirst on how to get transactions in to HubSpot that result from this self-serve form. However, no integration hows to pass those transactions are included in this line item. Contingency hours and/or a change order will be required if Aptitude 8 is needed to pass transactions to HubSpot. - Assumed is from form submit, all of the same things happen: policy certificate generated, transactional emails sent, etc. These are automations that should be set up separately outside of this line item and should include the self-serve scenario. | F35: 60 | G35: 60
A37: • | B37: Transactional Email Migration | F37: =IFERROR(__xludf.DUMMYFUNCTION("ROUNDUP( ( SUM( INDIRECT( ""F""&(ROW()+1)&"":F""& IFERROR( INDEX( FILTER( ROW(A:A), REGEXMATCH(A:A, ""^[•◆■※⊳]""), ROW(A:A) > ROW() ), 1 "&" )-1, 999 ) ) )+ SUM( INDIRECT( ""G""&(ROW()+1)&"":G""& IFERROR( INDEX( FILTER( ROW(A:A), REGEXMATCH(A:A, ""^[•◆■※⊳]""), ROW(A:A) "&"> ROW() ), 1 )-1, 999 ) ) ) )/2 )"),20.0) -> 20 | H37: Standard
B38: Transactional Email Migration | C38: Warranty First has a series of transactional emails that are sent to Planholders throughout their customer journey that need to be replicate in HubSpot so Planholders are aware of key policy updates and events. | D38: Replicate transactional emails, ensure personalization tokens are confirmed and tested, implement the automations to deliver the emails | E38: - This sheet is considered source of truth for the transactional emails that need to be created. - Aptitude 8 will create up to 10 transactional email automations using workflows. NOT via API. - Aptitude 8 will create the emails but require WarrantyFirst to provide a template Aptitude 8 can easily use - Transactional email add-on is required and as a result, the WarrantyFirst team can deprecate Mandrill | F38: 20 | G38: 20
A41: • | B41: Repair Requests Process Implementation | F41: =IFERROR(__xludf.DUMMYFUNCTION("ROUNDUP( ( SUM( INDIRECT( ""F""&(ROW()+1)&"":F""& IFERROR( INDEX( FILTER( ROW(A:A), REGEXMATCH(A:A, ""^[•◆■※⊳]""), ROW(A:A) > ROW() ), 1 "&" )-1, 999 ) ) )+ SUM( INDIRECT( ""G""&(ROW()+1)&"":G""& IFERROR( INDEX( FILTER( ROW(A:A), REGEXMATCH(A:A, ""^[•◆■※⊳]""), ROW(A:A) "&"> ROW() ), 1 )-1, 999 ) ) ) )/2 )"),120.0) -> 120 | H41: High
B42: Repair Requests Process Build | C42: Warranty First needs the ability to intake, track, and manage claims so they can deliver their services to Planholders, collaborate with auto body shops, and keep dealers informed. | D42: Aptitude 8 should identify which parties are involved, what inputs from which parties are requirement WHEN, and what reporting is needed to more meaningful track claims, compared today. | E42: - One intake form on the website, one for the Planholder portal (28 min mark of gong) - One claim pipeline to show claim status at any given time - One conversation inbox for claims team - One ticket pipeline to keep support requests seperate from claims and to associate claims to tickets where applicable - Up to 5 skills created and up to 5 rules for assignment created - Up to 1 ticket assignment workflow for each pipeline based on the type of ticket and/or the skills required to assign - One form for body shops to submit their assessments and associate to claims. This does not include a landing page nor does it include for Aptitude 8 to embed the form. - One form for parts required to fix the vehicle for the auto body shop to submit. This does not include a landing page nor does it include for Aptitude 8 to embed the form. - Custom code action to act as a validation engine to ensure a claim submitted is covered by the Planholders plan. WarrantyFirst must provide the specs for validation in order to successfully implement this automation. - Custom code action to act as a validation engine to ensure details the body shop is uploading to the claim are covered under the plan. WarrantyFirst must provide the specs for validation in order to successfully implement this automation. | F42: 120 | G42: 120
A46: • | B46: Dealership Portal Implementation | F46: =IFERROR(__xludf.DUMMYFUNCTION("ROUNDUP( ( SUM( INDIRECT( ""F""&(ROW()+1)&"":F""& IFERROR( INDEX( FILTER( ROW(A:A), REGEXMATCH(A:A, ""^[•◆■※⊳]""), ROW(A:A) > ROW() ), 1 "&" )-1, 999 ) ) )+ SUM( INDIRECT( ""G""&(ROW()+1)&"":G""& IFERROR( INDEX( FILTER( ROW(A:A), REGEXMATCH(A:A, ""^[•◆■※⊳]""), ROW(A:A) "&"> ROW() ), 1 )-1, 999 ) ) ) )/2 )"),120.0) -> 120 | H46: High
B47: Content Hub Memberships Setup | C47: Warranty First needs memberships set up appropriate for each portal: dealerships and planholders. | D47: Set up memberships lists, system pages, system emails, etc that sets the team up for a easy transition to HubSpot | E47: - Aptitude 8 assumes WarrantyFirst will pick a templated theme on the CMS marketplace and therefore Aptitude 8 will make modifications to the template to ensure it complies with WarrantyFirst requirements. Aptitude 8 will consult WarrantyFirst on implications of choosing different themes and if it impacts scope. - Aptitude 8 will set up the basic memberships configuration to power the membership portal: lists, page access, testing, and system emails - There are 2 portals being created: 1 for dealership contacts and 1 for Planholders - Aptitude 8 will create a workflow to add the appropriate dealer contacts to a memberships list. This memberships list will trigger an account create email (transactional). - Aptitude 8 will create a manual repeatable process to import dealer contacts into HubSpot and teach the WarrantFirst team how to do this. | F47: 15 | G47: 15 | I47: Development
B48: Dealership Portal | C48: Warranty First requires dealerships have access to the policies they have sold, their claims, and the ability to add a new policy for their customers. | D48: Aptitude 8 should finalize format/style requirements as well as functionality requirements before building the dealership portal on Content Hub's functionality. | E48: - Ability for dealership to add a policy (build a quote proof of concept as foundation) which includes referencing pricing objects in HubSpot and includes tax - Ability to call and return vehicle information from an external database WarrantyFirst provides Aptitude 8 access to. This database must have stable APIs or a change order will result. - Ability to run approval process on policies submitted by a dealership - Ability for dealership to see the count of claims, their IDs, and status, only - Aptitude 8 will create 1 CRM card for the cover level object, or which ever name(s) we use for objects represent pricing, in the middle pane so it is easy for Admins to update pricing related to a customer - Aptitude 8 will not provide design work for the portal. However, Aptitude 8 will consult the WF team on design to ensure it's within budget and HubSpot friendly. | F48: 105 | G48: 105 | I48: Development
A50: • | B50: Planholder Portal Implementation | F50: 80 | H50: High
B51: Planholder Portal | C51: Warranty First requires planholders have access to the policies they have held over time, their claims, modify contact information, and have the ability to self-serve a renewal or new policy all together to lighten the burden of the WarrantyFirst sales and service teams. | D51: Aptitude 8 should finalize format/style requirements as well as functionality requirements before building the planholders portal on Content Hub's functionality. | E51: - Planholders are dealership customers who also purchase a warranty, white labeled by Warranty First - Aptitude 8 will create a one page branded planholder portal that allows policy holders to see table views of their policies, claims, and ability to modify contact information, submit a claim, or start a support ticket. - June Addition: Aptitude 8 will embed a screen/page for Planholders to create their own quote and pay for it in their portal experience. The expectation is the same inputs and checkout experience is created as this current process, however, we will need to ensure all transactions flow into HubSpot to reflect it, the Planholder has access to a certificate in their portal when they pay, and all other transactional emails are sent to the Planholder when they pay for a new policy or renew a policy. If inputs from the current widget change or downstream actions change, a change order will result. - Aptitude 8 will not provide design work for the portal. However, Aptitude 8 will consult the WF team on design to ensure it's within budget and HubSpot friendly. | F51: 80 | G51: 80 | I51: Development
A53: • | B53: Training & Documentation | F53: =IFERROR(__xludf.DUMMYFUNCTION("ROUNDUP( ( SUM( INDIRECT( ""F""&(ROW()+1)&"":F""& IFERROR( INDEX( FILTER( ROW(A:A), REGEXMATCH(A:A, ""^[•◆■※⊳]""), ROW(A:A) > ROW() ), 1 "&" )-1, 999 ) ) )+ SUM( INDIRECT( ""G""&(ROW()+1)&"":G""& IFERROR( INDEX( FILTER( ROW(A:A), REGEXMATCH(A:A, ""^[•◆■※⊳]""), ROW(A:A) "&"> ROW() ), 1 )-1, 999 ) ) ) )/2 )"),30.0) -> 30 | H53: Standard
B54: Training & Documentation | C54: Warrant First needs to train their users on how to use HubSpot generally, but also how to manage the custom stages and solution that is built as part of this project | D54: A8 will conduct up to 3 60 minute live training programs with end users, 2 60 minute train the trainer sessions, provide documentation and training guides, and provide post go live support for a period of 1 week | E54: - WarrantyFirst to facilitate scheduling and distribution of training assets. - Up to 5 hours in open office hours - Aptitude 8 will hold at least 3 live training sessions for each team, at least 2 live trainings with admins, and deliver custom documentation on custom processes built so WarrantyFirst can manage their instance post launch. | F54: 30 | G54: 30
A56: • | B56: Contingency Hours | F56: =IFERROR(__xludf.DUMMYFUNCTION("ROUNDUP( ( SUM( INDIRECT( ""F""&(ROW()+1)&"":F""& IFERROR( INDEX( FILTER( ROW(A:A), REGEXMATCH(A:A, ""^[•◆■※⊳]""), ROW(A:A) > ROW() ), 1 "&" )-1, 999 ) ) )+ SUM( INDIRECT( ""G""&(ROW()+1)&"":G""& IFERROR( INDEX( FILTER( ROW(A:A), REGEXMATCH(A:A, ""^[•◆■※⊳]""), ROW(A:A) "&"> ROW() ), 1 )-1, 999 ) ) ) )/2 )"),108.0) -> 108 | H56: High
...

Sheet New Stories
A1: co | C1: WarrantyFirst Customer Stories
B2: Service | C2: Customer Story | D2: Suggested Path | E2: Assumptions | F2: Estimated Low Hours | G2: Estimated High Hours | H2: Potential Variance | I2: Function | J2: Difference
B4: Warranty First provides car, van, and bike protection direct to customers and through a network of dealers. The Warranty First team has been using various tools to manage relationships with their clients and dealers via CRM related activities and portals to make it easy for their end users to interact with them. Recently, it's become apparent that there are some challenges within their current stack and the team has been exploring different options to unify these activities to streamline and standardize processes across the org. A true digital transformation journey. HubSpot became a strong contender due to its ease of use and customizable capabilities that will allow Warranty First and their GTM teams to operate under one umbrella. By leveraging sales, marketing, and custom portal offerings within HubSpot, the Warranty First team will be able to streamline and automate sales efforts, dealer portal interactions, and claim management processes. Warranty First requires a scalable data architecture that allows them to manage and standardize sales and marketing activities in one place. A comprehensive approach to data quality, process management, and automation is necessary.
A5: • | B5: Requirements + Solutioning Workshops | F5: =IFERROR(__xludf.DUMMYFUNCTION("ROUNDUP( ( SUM( INDIRECT( ""F""&(ROW()+1)&"":F""& IFERROR( INDEX( FILTER( ROW(A:A), REGEXMATCH(A:A, ""^[•◆■※⊳]""), ROW(A:A) > ROW() ), 1 "&" )-1, 999 ) ) )+ SUM( INDIRECT( ""G""&(ROW()+1)&"":G""& IFERROR( INDEX( FILTER( ROW(A:A), REGEXMATCH(A:A, ""^[•◆■※⊳]""), ROW(A:A) "&"> ROW() ), 1 )-1, 999 ) ) ) )/2 )"),410.0) -> 410 | H5: Standard
A6: Current Phase: Actual Hours Usage | B6: Requirements Gathering | C6: WarrantyFirst's business objective is to create a cohesive business data, systems, process, and people roadmap that addresses their ideal future state, supports growth and adapts to evolving business needs. | D6: Conduct Discovery and Requirements Gathering Sessions & Produce a summary recommendations document including a detailed documentation of the current state as well as the future state business and technical requirements, including comprehensive diagrams detailing data model, process, integrations, and reporting details. | E6: - Aptitude 8 will prioritize the following workstreams: marketing, sales, operations, data, and integrations. | F6: 120 | G6: 120 | I6: Solutions Engineering, Strategy, Consulting
A7: Current Phase: Actual Hours Usage | B7: Data Model & Systems Architecture Strategy | C7: Warranty First needs to define a HubSpot data model that reflects their business in order to run sales processes and servicing proceses effectively at scale. | D7: Aptitude 8 should run a data modeling exercise to finalize objects, relationships, and properties for migration purposes and for future growth. They should also identify which objects map between which systems. | E7: - Aptitude 8 will create an ERD that defines object definitions, associations and association types, and up to 5 key properties. - Aptitude 8 will create data migration diagram to show how existing data maps to HubSpot - Aptitude 8 will create a basic visual to demonstrate how data flows between systems: what data maps and in what direction - Aptitude 8 will ensure the correct field level permissions are finalized before creating all fields | F7: 180 | G7: 180 | I7: Solutions Engineering, Strategy, Consulting
A8: Current Phase: Actual Hours Usage | B8: Proof of Concept/Solutioning | C8: WarrantyFirst desires a collaborative engagement to solve for key business and technical requirements. | D8: Plan workshops to solve for key workstreams, discuss options, and decide on a path forward. | E8: - Aptitude 8 will guide WarrantyFirst through a series of workshops that help them understand how they can solve for business and technical requirements. - Aptitude 8 might use hours in this line item to build proof of concept's to demonstrate how different options will look and function. | F8: 25 | G8: 25 | I8: Solutions Engineering, Strategy, Consulting
A9: Current Phase: Actual Hours Usage | B9: Portal Migration Strategy | C9: Warranty First needs to migrate current users to HubSpot so they can access the new portal(s). | D9: Aptitude 8 should recommend a plan that highlights the WHAT, HOW, and WHEN to migrate users to the new portals. | E9: - Up to 10 advisory hours to assist the WarrantyFirst team - Aptitude 8 will not manage any communications such as emails, SMS, or calls, nor automations required to complete the transition. Example: Aptitude 8 will not setup emails to inform current planholders or dealer contacts of the move to HubSpot's customer portal BUT Aptitude 8 will consult on best ways to approach this considering their HubSpot expertise. | F9: 60 | G9: 60 | I9: Solutions Engineering, Strategy, Consulting
A10: Current Phase: Actual Hours Usage | B10: Project Planning | C10: WarrantyFirst desires a roadmap that details what needs to be done by when by who as they migrate the new company into their business. | D10: Create a gantt chart with first and second level dependencies to prepare WarrantyFirst's team for an all hands on deck approach. Finalize project decisions are made in this phase at the latest. | E10: - Aptitude 8 will ensure each workstream has a dedicated owner, milestones are defined, drop dead dates are denoted - Aptitude 8 will create a Gantt chart as source of truth for the project plan for key integrations, marketing and sales processes, and key record and other asset migration | F10: 25 | G10: 25 | I10: Strategy, Project Management
A12: • | B12: HubSpot Configuration - Data Model, Users, and Permissions | F12: =IFERROR(__xludf.DUMMYFUNCTION("ROUNDUP( ( SUM( INDIRECT( ""F""&(ROW()+1)&"":F""& IFERROR( INDEX( FILTER( ROW(A:A), REGEXMATCH(A:A, ""^[•◆■※⊳]""), ROW(A:A) > ROW() ), 1 "&" )-1, 999 ) ) )+ SUM( INDIRECT( ""G""&(ROW()+1)&"":G""& IFERROR( INDEX( FILTER( ROW(A:A), REGEXMATCH(A:A, ""^[•◆■※⊳]""), ROW(A:A) "&"> ROW() ), 1 )-1, 999 ) ) ) )/2 )"),30.0) -> 30 | H12: High
A13: No change | B13: Data Model Build | C13: Warranty First needs to define a HubSpot data model that reflects their business to run sales and servicing processes effectively at scale, including custom objects for Plans, Vehicles, Pricing Rules, and Invoices. | D13: Implement the defined data model, including standard objects (Contacts, Companies, Deals, Tickets) and custom objects (Vehicles, Pricing Rules, Dealer Targets, Xero Invoices) with all specified properties and associations. | E13: Up to 30 custom properties per standard object and 6 custom objects: Policies, Claim Items, Cover Levels, Xero Invoices, and Vehicles. The model must support the quoting logic, repair requests, and billing processes. | F13: 20 | G13: 20 | I13: Development
A14: No change | B14: Users & Permissions | C14: Warranty First needs to implement a role-based access control system to ensure Dealer Managers and Dealer Staff have appropriate portal and CRM access. | D14: Configure HubSpot user roles, teams, and permissions to enforce the defined Dealer Manager (full access, financial visibility) and Dealer Staff (operational access only) roles in the portal. | E14: Up to 50 sales users, 10 teams, and 10 admin/exec seats. Permissions must isolate dealer data and restrict access to billing/financial metrics for Dealer Staff. | F14: 10 | G14: 10 | I14: Development
A16: • | B16: HubSpot Implementation - SalesHub | F16: 70 | H16: High
A17: No change | B17: CRM Migration | C17: Warranty First needs to migrate historical customer, dealer, and plan records into HubSpot to ensure business continuity and historical reporting capability. | D17: Advise on CSV formatting and import historical records, including dealer records, user contacts, planholders, policies, claims, auto body shops, and pricing tables. | E17: Warranty First is responsible for preparing and delivering final, HubSpot-ready CSV files, including all data extraction, cleanup, deduplication, normalization, validation, legacy ID mapping, and association preparation, and must correct any data issues identified during import. Aptitude 8 is responsible for validating the provided CSV files, configuring HubSpot objects and properties, executing and sequencing imports, running post-import workflows and associations, migrating documents, performing quality assurance, and supporting user acceptance testing with minor HubSpot-side adjustments. Aptitude 8 will not perform source data extraction, cleanup, deduplication, or transformation, and any changes to the data model or additional datasets are out of scope and may require additional hours. All delivered CSV files must be structurally valid, HubSpot-compliant, complete, consistent, and importable without systemic data errors. | F17: 50 | G17: 50 | I17: Development
A18: Descoped | B18: Implement HubSpot Calling | C18: Warranty First is seeking to modernize its telephony stack and calling workflows to better integrate with HubSpot, improve call visibility, enable coaching and sentiment analysis, and ensure accurate reporting of call activity across teams. Rather than adopting HubSpot’s native calling in isolation, Warranty First is evaluating third-party telephony providers with native HubSpot integrations (e.g., Aircall, RingCentral) to ensure the solution meets both current operational needs and future-state requirements. | D18: Warranty First requires guidance to identify a telephony provider that: - Natively and reliably integrates with HubSpot - Supports flexible, app-based calling (moving away from traditional landlines) - Routes inbound calls appropriately across teams - Captures rich call data within HubSpot for reporting and coaching - Provides a foundation for advanced capabilities such as sentiment analysis and call insights | E18: Assumption – Call System & HubSpot Integrations: WF is procuring a new call system that is a HubSpot-supported provider. The selected call system vendor will be responsible for delivering, maintaining, and supporting all required HubSpot integrations related to calling functionality. As a result, any call system–related HubSpot integrations are excluded from Aptitude 8’s scope. | F18: -- | G18: -- | I18: Development
A19: No change | B19: Reporting and Dashboards | C19: Warranty First aims for enhanced reporting capabilities in HubSpot to obtain accurate insights into customer journeys, sales performance, dealer goals, and renewal opportunities. | D19: Aptitude 8 will configure up to (10) custom reports and (3) dashboards for Warranty First sales and claims team. | E19: - Up to 10 custom reports, 2 custom dashboards. - Up to 3 OOTB dashboards with filter only customization to their reports. | F19: 20 | G19: 20 | I19: Development, Consulting
A21: • | B21: Field Sales & Small Dealerships Process Implementation | F21: =IFERROR(__xludf.DUMMYFUNCTION("ROUNDUP( ( SUM( INDIRECT( ""F""&(ROW()+1)&"":F""& IFERROR( INDEX( FILTER( ROW(A:A), REGEXMATCH(A:A, ""^[•◆■※⊳]""), ROW(A:A) > ROW() ), 1 "&" )-1, 999 ) ) )+ SUM( INDIRECT( ""G""&(ROW()+1)&"":G""& IFERROR( INDEX( FILTER( ROW(A:A), REGEXMATCH(A:A, ""^[•◆■※⊳]""), ROW(A:A) "&"> ROW() ), 1 )-1, 999 ) ) ) )/2 )"),55.0) -> 55 | H21: Standard
A22: No change | B22: Pipeline Configuration | C22: Warranty First needs separate deal pipelines for new policy sales and new business (dealer acquisition) to track opportunities and process submitted policies. | D22: Create one deal pipeline for New Business (Dealer Acquisition) and one deal pipeline for Plans submitted by dealerships and/or by Self-Serve (Policy Submitted, In Approval, Closed Won/Lost). | E22: Field Sales and Smaller Dealership deals may coexist within the same pipeline, with segmentation achieved through Deal Owner assignment. Pipeline stages and required properties will be configured to appropriately support each distinct sales process. | F22: 10 | G22: 10 | I22: Development
A23: No change | B23: Process Automation | C23: Automate internal sales processes, manage call/meeting types, and ensure sales activity is tracked in HubSpot for accurate reporting. | D23: Create up to 3 call & meeting types with defined outcomes. Integrate reps' calendars and emails for automatic tracking of activities. | E23: All reps on the field sales team integrate their calendar/emails. | F23: 15 | G23: 15 | I23: Development
A24: Slight increase due to complexity | B24: Sales Territory Assignment | C24: Warranty First needs a robust, automated solution to ingest dealer company and contact data and automatically assign them to the correct sales representatives based on geographic territories. The goal is to ensure accurate, automated ownership, streamline the assignment process, maintain data integrity, and allow flexibility for future enhancements. | D24: Implement logic to assign deals and dealers based on sales territory to support Field Sales and Account Management structure. | E24: This work assumes implementation aligns with the approved design documentation (HERE), which serves as the source of truth for functionality, data flow, and system behavior. For the territory migration, source tables will be flattened and combined into two HubDB tables (Field Sales and Small Dealer Territories) with legacy IDs preserved. The custom User property “Territory” will replace territory_person relationships using an enumeration of all unique territory names (duplicates allowed across channels). Data will be imported from two files, and HubSpot users will be manually assigned the correct territory post-migration. Warranty First will replace all legacy “AG” postal codes with valid postal codes prior to migration. Warranty First is responsible for ensuring dealer records are cleaned; City and State fields contain valid values, and postal codes are moved into the proper Postal Code field. | F24: 15 | G24: 15 | I24: Development
A25: No Change | B25: Dealer Agreement Template | C25: Automate the creation and signing of partnership agreements for new dealerships to formalize the sales process. | D25: Create a basic quote template with e-sign and approval workflow to send to new dealership partners at the end of the Field Sales process. | E25: Basic quote template, e-signature is included, and no pricing/payment is listed on the quote. | F25: 15 | G25: 15 | I25: Development
A27: • | B27: Renewals Process Optimization & Implementation | F27: 95 | H27: Standard
A28: Slight increase due to new pipeline and increased automation. | B28: Auto-Generate Renewal Lead | C28: Warranty First needs a lead pipeline to accurately track and manage prospecting efforts for renewal leads. | D28: Create a renewal lead pipeline with stages and properties necessary for tracking renewal opportunities and customer eligibility status. Use the existing 'Plans' deal pipeline to track plan getting renewed. Automation to trigger on expiration date, create new lead record, copy vehicle data to the lead, and assign lead to contact owner. Automation to assign a new lead round robin to the TeleSales Team if the contact record is unassigned. Automation to trigger notification if ownership has been assigned to lead but no activity within a set number of days. Automation to trigger based on defined criteria, which will set the lead's label to hot, warm, or cold. Automation to trigger based on lead in qualified stage, creating deal in Plans pipeline (Deal associated with contact and lead). | E28: Workflow logic uses approved policy details (plan specs, dates, contact) to create the renewal deal. Renewal lead will have contact, vehicle, original plan records associated. | F28: 20 | G28: 20 | I28: Development
A29: No change | B29: Create a Quote/Plan CRM Card | C29: Enable the internal team to efficiently quote and create new or renewal plans directly within HubSpot CRM for planholders. | D29: Develop the "Create Plan UI Extension" that mirrors the Planholder Portal quoting flow, including vehicle lookup, pricing, discount entry (0-25%), Bumper payment link generation, and Deal creation. | E29: This work assumes implementation aligns with the approved design documentation (HERE), which serves as the source of truth for functionality, data flow, and system behavior. Must use the unified Pricing Resolver and ClearVehicleData integration. Requires Bumper payment link generation and Deal record creation with appropriate status and associations. | F29: 75 | G29: 75 | I29: Development
B31: Plan Lifecycle Automation Components | F31: 124 | H31: High
A32: New | B32: Auto Approval Engine | C32: Automate the approval process for new plans based on business rules to streamline activation. | D32: Implement the logic to automatically validate plans against vehicle factors, customer factors, and policy submission factors, setting the deal status to "Approved" or "Pending Approval". | E32: This work assumes implementation aligns with the approved design documentation (HERE), which serves as the source of truth for functionality, data flow, and system behavior. Auto-approval must incorporate age/mileage tolerances with surcharges, and flag for manual review based on criteria (e.g., import status, manual data entry, customer/dealer email match). | F32: 25 | G32: 25 | I32: Development
A33: No change | B33: Clear Vehicle Data Integration | C33: Integrate an external service to validate vehicle registration numbers and return detailed vehicle specifications for quoting. | D33: Build a universal serverless function (Node.js) on HubSpot Functions to connect to the ClearVehicleData API for VRN lookup, data validation, and return of key vehicle attributes to all front-end and CRM UI Extension quoting flows. | E33: This work assumes implementation aligns with the approved design documentation (HERE), which serves as the source of truth for functionality, data flow, and system behavior. ClearVehicleData API must be stable and accessible. Function must return required fields including Make, Model, Year, Engine Size, Manufactured Date, and Import Status. | F33: 12 | G33: 12 | I33: Development
A34: New | B34: Bumper Integration | C34: Integrate Bumper for payment processing across all direct sales and portal plan creation flows. | D34: Build a serverless function to initiate Bumper payment links and a webhook handler workflow to receive payment status updates, automatically marking the Plan record as "Paid" in HubSpot. | E34: This work assumes implementation aligns with the approved design documentation (HERE), which serves as the source of truth for functionality, data flow, and system behavior. Integration supports Pay Now and Pay Later options. Payment status updates must reliably update the Plan record's dealstage to "Paid". | F34: 26 | G34: 26 | I34: Development
A35: New | B35: Call Assist Integration | C35: Implement a data transfer process to send new and cancelled Call Assist Recovery plans to the vendor. | D35: Develop an automated external integration (e.g., Pipedream) to nightly query HubSpot for "Recovery" plans, generate a CSV file, and upload it to the Call Assist SFTP server. | E35: This work assumes implementation aligns with the approved design documentation (HERE), which serves as the source of truth for functionality, data flow, and system behavior. Integration runs nightly, queries for Plans where product_name includes "Recovery" and plan_status is "Approved" (new) or "Cancelled"/"Expired" (updates). Assumes hosting service (Pipedream-like) with static IP. | F35: 46 | G35: 46 | I35: Development
A36: No change | B36: Document Generation: Certification of Warranty Generation | C36: Automate the generation and delivery of the Warranty Certificate and other plan documents upon plan activation. | D36: Implement a HubSpot workflow utilizing document generation logic to create a PDF certificate per Warranty First's specs upon plan approval/payment, and deliver via transactional email. | E36: Plan documents are static PDFs stored in HubSpot File Manager once generated. Each update to planholder contact info triggers document regeneration workflow. GDPR-compliant anonymization and data deletion workflows handled manually by internal staff upon request. | F36: 15 | G36: 15 | I36: Development
B38: Pricing & Rating Automation | F38: 200 | H38: High
A39: New | B39: Build Pricing Engine | C39: Create a unified, single-source pricing engine to power all quoting channels (Dealer, D2C, Internal). | D39: Implement the Pricing Resolution Logic (Pricing Resolver) as a single serverless function that uses the Pricing Rules Custom Object to filter for context (Dealer/Direct/Public), apply base pricing, and calculate surcharges or discounts. | E39: This work assumes implementation aligns with the approved design documentation (HERE), which serves as the source of truth for functionality, data flow, and system behavior. Pricing engine must use the Pricing Rules custom object and enforce the defined logic for overrides, vehicle eligibility, and surcharges. | F39: 40 | G39: 40 | I39: Development
A40: New | B40: Centralized Pricing Management: Global Pricing CRM App | C40: Provide administrators with a central tool to manage base pricing bands system-wide. | D40: Implement the "Global Pricing Admin UI Extension" on the App Home Page for Pricing Administrators to create, edit, disable, and manage base price bands by year, which writes directly to the Pricing Rules Custom Object. | E40: This work assumes implementation aligns with the approved design documentation (HERE), which serves as the source of truth for functionality, data flow, and system behavior. Access restricted to Pricing Administrators. Must support versioning (year) and bulk editing/saving. | F40: 60 | G40: 60 | I40: Development | J40: The Global Pricing App sets the default list price, the Special Vehicle App creates an optional price overlay for specific vehicles, and the Dealer Pricing App is a local tool used by account managers to set a custom price just for that one dealership. All three layers are consumed by the single Pricing Resolver function during the quoting process.
A41: New | B41: Specialized Pricing Rules: Special Vehicle CRM App | C41: Provide administrators a dedicated interface to manage pricing exceptions for specific vehicle models. | D41: Implement the "Special Vehicle Pricing Management App Page" (Global App Home UI Extension) to manage rules stored in the Special Vehicle HubDB table, allowing for percentage or fixed amount adjustments for specific makes/models. | E41: This work assumes implementation aligns with the approved design documentation (HERE), which serves as the source of truth for functionality, data flow, and system behavior. Rules are stored in HubDB. Saving must automatically publish a new HubDB version for immediate use by the Pricing Resolver. | F41: 40 | G41: 40 | I41: Development
A42: New | B42: Dealer-Specific Pricing Controls: Dealer Pricing CRM App | C42: Enable Account Managers to manage custom pricing overrides for individual dealerships. | D42: Implement the "Dealer Pricing UI Extension" on the Company record center pane to view and edit custom retail prices per cover level for the specific dealer, writing overrides to the Pricing Rules Custom Object. | E42: This work assumes implementation aligns with the approved design documentation (HERE), which serves as the source of truth for functionality, data flow, and system behavior. Only Account Managers/Admins can access. Must override public pricing for the specific dealer context in the Resolver. | F42: 60 | G42: 60 | I42: Development
B44: D2C; Self-Serve Experience | F44: 30 | H44: High
A45: Decrease | B45: Self-Service Public D2C Purchase | C45: Provide a public-facing self-service purchase flow for non-authenticated customers to get a quote and purchase a plan. | D45: Build the "Self-Serve CMS Quoting Page" (multi-step guided wizard on HubSpot CMS) that uses the unified Pricing Resolver (D2C target), ClearVehicleData API, and Bumper payment integration to create Plan and Contact records upon successful payment. | E45: Webflow Hosted Platform Decision: The end-to-end subscription quoting and purchase experience will be hosted in an external Webflow platform, which differs from the original plan to use a HubSpot CMS page. Aptitude 8 (A8) is responsible for the Pricing Engine, while Tomorrow’s Journey (TJ Services) is responsible for the Webflow customer experience and the custom integration to sync data into HubSpot. These 30 hours account for Aptitude 8’s involvement in cross-vendor alignment, technical coordination, QA, and end-to-end testing required to ensure the Webflow experience, pricing engine, and HubSpot data sync operate seamlessly together. This work assumes Tomorrow's Journey's implementation aligns with the approved design documentation (HERE), which serves as the source of truth for functionality, data flow, and system behavior. | F45: 30 | G45: 30 | I45: Development
B47: Transactional Email Migration | F47: 20 | H47: Standard
A48: No Change | B48: Transactional Email Migration | C48: Replicate existing transactional emails in HubSpot and implement workflows to deliver them to planholders. | D48: Create up to 10 transactional email automations using HubSpot Workflows and replicate email content/personalization. | E48: - This sheet is considered source of truth for the transactional emails that need to be created. - Aptitude 8 will create up to 10 transactional email automations using workflows. NOT via API. - Aptitude 8 will create the emails but require WarrantyFirst to provide a template Aptitude 8 can easily use - Transactional email add-on is required and as a result, the WarrantyFirst team can deprecate Mandrill | F48: 20 | G48: 20 | I48: Development
B50: Repair Requests Process Implementation | F50: 120 | H50: High
...

Sheet Details
D1: Proposal + Project Details | G1: Warranty First aims to enhance their CRM functionality by integrating HubSpot with key business systems like QuickBooks and Power BI, streamlining financial management and analytical reporting. They prioritize automation of sales pipelines and customization of quotes to improve operational efficiency and customer engagement. A strategic partnership is sought for long-term optimization and scalability of their CRM ecosystem. Warranty First end goal is a cohesive, data-driven environment that supports growth and adapts to evolving business needs.
A2: • | B2: Deal Inputs | F2: Deal + Asset Links
B3: Company Name | F3: Google Folder
B4: Deal Record ID | F4: Deal Link
B5: Last Sync to HubSpot | C5: 45784.321 | F5: Solutions Architect
B6: Request Scope Review | D6: scoping_status | F6: Service Library Message
B7: Scope Reviewed | D7: scoped_reviewed
B9: Engagement Inputs
B10: NOW Project
B11: Hourly Project Rate | C11: 200 | D11: project_hourly_rate
B12: Project Management Factor | C12: 0.11
B13: SA Expected Start Date | C13: 45817
B14: Total Project Months | C14: 5 | D14: project_duration
B16: NEXT Retainer
B17: Hourly NEXT Retainer Rate | C17: 200 | D17: retainer_hourly_rate
B18: NEXT Hours Per Month | C18: 40 | D18: retainer_hours_per_month_sold
B19: NEXT Retainer Months | C19: 1 | D19: retainer_months_sold
B22: Calculated Project Details | F22: Calculated Ranges | G22: Low Hours | H22: High Hours
B23: Deal Amount | C23: {=INDEX(Overview!F:G, MATCH("⚑", Overview!A:A, 0), 1)} -> 232200 | D23: amount | F23: Service Estimates: | G23: =IFERROR(__xludf.DUMMYFUNCTION("ARRAYFORMULA( SUMIFS( Overview!F:F, Overview!F:F, "">0"", Overview!A:A, ""<>•*"", Overview!A:A, ""<>◆*"", ROW(Overview!A:A), "">""&MIN(IF(REGEXMATCH(Overview!A:A,""^•""),ROW(Overview!A:A))), ROW(Overview!A:A), ""<""&MIN(IF(REGEX"&"MATCH(Overview!A:A,""^※|^◆""),ROW(Overview!A:A),99999)) ) )"),991.0) -> 991 | H23: =IFERROR(__xludf.DUMMYFUNCTION("ARRAYFORMULA( SUMIFS( Overview!G:G, Overview!G:G, "">0"", Overview!A:A, ""<>•*"", Overview!A:A, ""<>◆*"", ROW(Overview!A:A), "">""&MIN(IF(REGEXMATCH(Overview!A:A,""^•""),ROW(Overview!A:A))), ROW(Overview!A:A), ""<""&MIN(IF(REGEX"&"MATCH(Overview!A:A,""^◆""),ROW(Overview!A:A),99999)) ) )"),991.0) -> 991
B24: Total Engagement Hours Sold | C24: =SUMIFS(Overview!F:F, Overview!A:A, "*•*") + SUMIFS(Overview!F:F, Overview!A:A, "*◆*") + SUMIFS(Overview!F:F, Overview!A:A, "*■*") -> 1161 | D24: sold_hours | F24: Project Management: | G24: =G23 * C12 -> 109.01 | H24: =H23 * C12 -> 109.01
B25: Total Project Hours Sold | C25: =SUMIFS(Overview!F:F, Overview!A:A, "*•*") + SUMIFS(Overview!F:F, Overview!A:A, "*◆*") -> 1121 | D25: project_hours_sold | F25: Post-Project Support: | G25: {=INDEX(Overview!F:G, MATCH("■*", Overview!A:A, 0), 1)} -> 40 | H25: {=INDEX(Overview!F:G, MATCH("■*", Overview!A:A, 0), 1)} -> 40
B26: Total Retainer Hours Sold | C26: =SUMIFS(Overview!F:F, Overview!A:A, "*■*") -> 40 | F26: Hour Estimates: | G26: =SUM(G23:G25) -> 1140.01 | H26: =SUM(H23:H25) -> 1140.01
B27: Expected End Date | C27: =EDATE(C13, C14) -> 45970 | F27: Investment Ranges: | G27: =G26*C11 -> 228002 | H27: =H26*C11 -> 228002
B28: Expected Project Hours/Month | C28: =roundup(C25/C14,0) -> 225
B29: Linear Expected Project Hours/Week | C29: =roundup(C28/4.3,0) -> 53 | F29: Total Estimated Engagement Hours: | G29: =SUMIFS(Overview!F:F, Overview!A:A, "*•*") + SUMIFS(Overview!F:F, Overview!A:A, "*◆*") + SUMIFS(Overview!F:F, Overview!A:A, "*■*") -> 1161
B30: Peak Project Expected Hours | C30: =C29*1.2 -> 63.6 | F30: Total Estimated Investment: | G30: {=INDEX(Overview!F:G, MATCH("⚑", Overview!A:A, 0), 1)} -> 232200
B31: Low Project Expected Hours | C31: =C29*0.5 -> 26.5
B32: Dev Work Percentage | C32: =C39/C44 -> 0.17841213 | D32: dev_work_pct
B33: SE Work Percentage | C33: =C41/C44 -> 0 | D33: se_work_pct
A36: ※ | B36: Calculated Function Summary | F36: SOW Summarized Line Items
B37: =IFERROR(__xludf.DUMMYFUNCTION("LET( square_row, MATCH(""■"", Overview!A:A, 0) - 1, valid_range, SEQUENCE(square_row), raw_calcs, QUERY( ARRAYFORMULA({ IF(INDIRECT(""Overview!I1:I""&square_row) = """", ""Unassigned"", INDIRECT(""Overview!I1:I""&square_row)), IF( "&" REGEXMATCH(INDIRECT(""Overview!A1:A""&square_row), ""•""), 0, IF( REGEXMATCH(INDIRECT(""Overview!A1:A""&square_row), ""◆""), INDIRECT(""Overview!F1:F""&square_row), (INDIRECT(""Overview!F1:F""&square_row"&") + INDIRECT(""Overview!G1:G""&square_row))/2 ) ) }), ""select Col1, sum(Col2) where Col1 is not null and Col2 is not null group by Col1 label Col1 'Function', sum(Col2) 'Hours'"", 0 ), functions, {""F"&"unction"", ""Hours""; ""Consulting"", IFERROR(VLOOKUP(""Consulting"", raw_calcs, 2, FALSE), 0); ""Development"", IFERROR(VLOOKUP(""Development"", raw_calcs, 2, FALSE), 0); ""Project Management"", IFERROR(VLOOKUP("&"""Project Management"", raw_calcs, 2, FALSE), 0); ""Solutions Engineering"", IFERROR(VLOOKUP(""Solutions Engineering"", raw_calcs, 2, FALSE), 0); ""Strategy"", IFERROR(VLOOKUP(""Strategy"", raw_calcs, 2, FALSE), 0); "&" ""Unassigned"", IFERROR(VLOOKUP(""Unassigned"", raw_calcs, 2, FALSE), 0)}, functions )"),"Function") -> Function | C37: =IFERROR(__xludf.DUMMYFUNCTION("""COMPUTED_VALUE"""),"Hours") -> Hours | D37: Percent of | F37: =IFERROR(__xludf.DUMMYFUNCTION("QUERY( Overview!A7:F58, ""select B, F where (A = '•' or A = '◆' or A = '■') and B is not null"" )"),"Requirements + Solutioning Workshops") -> Requirements + Solutioning Workshops | G37: =IFERROR(__xludf.DUMMYFUNCTION("""COMPUTED_VALUE"""),150.0) -> 150
