Workbook

Sheet Overview
A1: lea | C1: ForceBrands Master Customer Story
B2: Service | C2: Customer Story | D2: Suggested Path | E2: Assumptions | F2: Estimated Low Hours | G2: Estimated High Hours | H2: Potential Variance | I2: Function | J2: POC
B4: Executive Summary | E4: Additional Notes + Considerations
B5: ForceBrands is a specialized recruitment firm serving CPG, food & beverage, and retail industries and they are seeking to consolidate sales operations in HubSpot Sales Hub while maintaining recruitment workflows in Bullhorn. This migration addresses critical challenges including limited sales/marketing visibility, incomplete revenue attribution, and process inefficiencies caused by platform limitations and fragmentation. ForceBrands currently operates both sales and recruitment functions within Bullhorn. The sales and marketing teams lack transparency, manual handoffs create inefficiencies, and the existing Linkfuse integration requires replacement with a more robust solution. A8 proposes an engagement and project that will migrate the entire sales team to HubSpot Sales Hub while preserving recruitment team workflows in Bullhorn through a custom bi-directional integration. This approach will enable complete marketing-to-revenue attribution, streamlined sales processes, and their specialized recruitment workflows that drive their core business model of retained search and contingency placements. In an effort to futher consolidate and optimize their tech stack, ForceBrands is also pursuing a website redesign and migration from Wordpress to HubSpot's CMS/Content Hub. This project component will be managed by another vendor, but has dependencies specific to the CRM migration project. A8 will require strong collboration with ForceBrands to ensure revenue-generating requirements are met. Scope Changelog: - Lowered website vendor consulting/collab 15 to 10 - Rebalanced PM hour allocation - Reblance of some discovery call allocation - Consolidated HubSpot configuration into Sales Hub Set-up - Additional sales services to support account management and feedback loop with marketing | E5: - The assumptions content in this scope are based on information and discovery during the sales evaluation and is subject to change during the project if additional challenges or barriers are discovered. - A8 is a Time & Materials agency, we will provide transparent budget tracking throughout the project and change orders will require approvals by ForceBrands. Project Risks: - As ForceBrands is transforming their technology across multiple departments and platforms at once, risk mitigation is paramount. A8 will surface perceived blockers and will inform ForceBrands of possible change orders promptly - Should the website timeline affect ForceBrand's Sales Hub/CRM migration and launch, A8 is recommending teams prioritize the CRM launch and then resume the web launch in a modified "Phase 2", requiring an additional scope of work. - "Duel" forms may need to trigger workflows, support list segmentation, or lead scoring to allow for existing lead management to continue to operate while not block net new lead managment processes Scope Confirmation Points: - Are there any other contract expirations or add-on/modules with Bullhorn? - Have pulled a majority of marketing implementation and training, assuming collaboration throughout the project - Data migration is assuming general record parity, with the exception of Opportunities and Jobs, no historical attachments sync'd via the integration - ForceBrands sales team to support internal configuration and set up
A7: • | B7: Discovery + Requirements Gathering: Gather and document ForceBrand's business + project requirements | F7: =IFERROR(__xludf.DUMMYFUNCTION("ROUNDUP( ( SUM( INDIRECT( ""F""&(ROW()+1)&"":F""& IFERROR( INDEX( FILTER( ROW(A:A), REGEXMATCH(A:A, ""^[•◆■※⊳]""), ROW(A:A) > ROW() ), 1 "&" )-1, 999 ) ) )+ SUM( INDIRECT( ""G""&(ROW()+1)&"":G""& IFERROR( INDEX( FILTER( ROW(A:A), REGEXMATCH(A:A, ""^[•◆■※⊳]""), ROW(A:A) "&"> ROW() ), 1 )-1, 999 ) ) ) )/2 )"),65.0) -> 65 | H7: High
B8: Sales Process Requirements Gathering Workshops | C8: ForceBrands needs Aptitude 8's strategic guidance to gather and organize requirements for their sales team's migration from Bullhorn to HubSpot, including understanding their contingency and retained search processes. | D8: A8 to host workshops with ForceBrands' sales teams and leadership to understand current Bullhorn usage, sales processes, and handoff points between marketing and recruiting teams. | E8: - Up to 4-5 meetings leveraging meeting time, agenda prep, and follow-up items - Workshops will cover pipeline structure for contingency/retained searches, Refills, and Search Confirmations - Deep dive into current Bullhorn workflows and data dependencies - ForceBrands to ensure all relevant stakeholders are available and support scheduling | F8: 12 | G8: 15 | I8: Strategy
B9: Marketing Process + Lead Management Requirements Gathering Workshops | C9: ForceBrands needs to align their existing Marketing Hub setup with new sales processes and define a new lead scoring framework that works across their website redesign project. | D9: A8 to review current Marketing Hub configuration and collaborate with ForceBrands and New Breed to define lead scoring requirements that bridge marketing automation and sales handoff. | E9: - Up to 3-4 workshops focusing on current marketing processes and lead quality definitions - Review of existing automation, lists, and workflows - Lead scoring criteria documentation for both marketing and recruiting qualified leads - ForceBrands to ensure all relevant stakeholders are available and support scheduling | F9: 8 | G9: 12 | I9: Strategy
B10: Go-to-Market Requirements Gathering Workshops | C10: ForceBrands' Marketing and Sales teams need Aptitude 8's strategic guidance to gather requirements for lead handoff processes, territory/vertical-based routing, and integration touchpoints with Bullhorn. | D10: A8 to host workshops with sales teams and marketing leadership to understand critical marketing-to-sales handoff points and required feedback loops between teams. | E10: - Up to 3-4 workshops covering lead routing, MQL processes, territory management, and recruiter data requirements - Assumes ForceBrands provides pre-work materials and stakeholder availability | F10: 8 | G10: 12 | I10: Strategy
B11: Tech Stack / Web Discovery | C11: ForceBrands's needs Aptitude 8's expertise and guidance to support their overall technology and architecture planning relative to HubSpot. | D11: A8 to host workshops with go-to-market and IT teams to align on existing net new platforms that affect the CRM project. | E11: - Up to 2-3 meetings to discuss ForceBrand's entire tech stack Workshops and discovery sessions will discuss the following: - Any other critical website-dependent projects or technologies - Data flow between HubSpot and Bullhorn today, versus future needs - Confirm any additional technologies Forcebrands is considering eg. Enrichment platforms, data warehouses, event/webinar platforms - Including firming up relational information between people and accounts - System of truth vs downstream data flows - Stakeholders and resource requirements may vary for these type of discovery sessions | F11: 4 | G11: 4 | I11: Solutions Engineering
B12: Bullhorn Integration Technical Discovery | C12: ForceBrands needs comprehensive technical requirements gathering for their custom Bullhorn integration to replace the native connector and support their unique recruiting workflows. | D12: A8 to conduct technical discovery sessions to document API requirements, data mapping needs, and bi-directional sync logic between HubSpot and Bullhorn ATS. | E12: - Up to 6-8 technical workshops with marketing, sales, and IT teams - A8 to begin documenting current Bullhorn data model and required objects (jobs, candidates, placements) - Map critical workflows that span both systems - Identify regular-schedule vs batch sync requirements - ForceBrands to support A8's Bullhorn Integration Partner Application process | F12: 26 | G12: 28 | I12: Solutions Engineering
A14: • | B14: Solutions Engineering / Project Planning / Final Scope Validation: Define and design a HubSpot instance to meet ForceBrand's needs | F14: =IFERROR(__xludf.DUMMYFUNCTION("ROUNDUP( ( SUM( INDIRECT( ""F""&(ROW()+1)&"":F""& IFERROR( INDEX( FILTER( ROW(A:A), REGEXMATCH(A:A, ""^[•◆■※⊳]""), ROW(A:A) > ROW() ), 1 "&" )-1, 999 ) ) )+ SUM( INDIRECT( ""G""&(ROW()+1)&"":G""& IFERROR( INDEX( FILTER( ROW(A:A), REGEXMATCH(A:A, ""^[•◆■※⊳]""), ROW(A:A) "&"> ROW() ), 1 )-1, 999 ) ) ) )/2 )"),34.0) -> 34 | H14: Standard
B15: Lead Journey Mapping + Go-to-Market Team Process Visualization | C15: ForceBrands needs documentation of their ideal lead management process across systems to ensure all stakeholders understand the new customer journey and how additional platforms interact with the data. | D15: A8 to map future state lead journeys, data transition points between systems, and identify process changes required for team adoption in HubSpot. | E15: - Cross-functional alignment between marketing and sales teams is required during the earlier discovery phase and meetings - Define ownership rules, DQ reason feedback back to marketing for segmentation - Specific trigger points for lead/account handoffs will be defined and visualized in Lucid Charts - Components of this documentation will serve as training material for broader team adoption | F15: 6 | G15: 8 | I15: Strategy
B16: Sales Process Design & Pipeline Architecture | C16: ForceBrands needs their complex recruiting sales processes mapped to HubSpot's pipeline structure, supporting both contingency and retained search models. | D16: A8 to design pipeline configurations, deal stages, and required properties to support contingency searches, retained searches, Refills, and Search Confirmations within HubSpot. | E16: - Design one pipeline with appropriate stages and exit criteria - Begin to map Bullhorn job/placement data to HubSpot deal stages and properties - Define automation triggers between pipeline stages - Account for different fee structures and billing models - Design approval workflows for different search types as required | F16: 6 | G16: 8 | I16: Strategy
B17: Tech Stack Design + Integrated Platform Strategy | C17: ForceBrands requires Aptitude 8's expertise to design a holistic HubSpot architecture that integrates seamlessly with their existing tech stack while ensuring proper data flow and maintaining system integrity. | D17: A8 to create a technical design document outlining platform and integration touchpoints for current state, transitory, and final Phase 1 launch. | E17: - Teams to define and design account and deal data structures and flow between platforms - Teams to begin to align around sandbox vs production strategy | F17: 2 | G17: 3 | I17: Solutions Engineering
B18: Data Migration Strategy & Data Mapping Support | C18: ForceBrands needs a strategic approach to migrate contacts (client and candidates), companies, and opportunities from Bullhorn to HubSpot, focusing on active and recent records while preserving critical relationship data. | D18: A8 to develop migration strategy determining what data moves via manual import vs backfilling via the custom integration, with emphasis on active clients, candidates, and recent opportunities. | E18: - Focus on records with activity in last 12-24 months - Define company hierarchy and association rules - A8 to consult on a strategy for deduplication across contact databases - Historical data (and attachments) to be addressed in Phase 2 - Define manual import vs. integration backfill sync strategy based on requirements and most effective path forward - A8 to support data mapping exercise with ForceBrands with a template - ForceBrands to implement all properties to support implementation and integration requirements (A8 will evaluate other property creation tools to faciliate faster creation) | F18: 10 | G18: 12 | I18: Solutions Engineering
B19: Project Planning + Roadmap / Final Scope Confirmation | C19: ForceBrands needs a detailed project plan that coordinates their HubSpot implementation with the concurrent website redesign while minimizing business disruption. | D19: A8 to create a comprehensive project plan with phases and project dependencies, coordinating touchpoints with New Breed's website project. | E19: - Clear dependencies mapped between website, CRM, and custom Bullhorn integration projects - Designated sales team migration from Bullhorn - Integration development milestones and testing phases Website Note: This service and component has a critical web project dependency | F19: 6 | G19: 6 | I19: Strategy
A21: • | B21: HubSpot Implementation - Marketing Hub: Primarily consult and support updates of ForceBrand's marketing process and HubSpot functionality | F21: =IFERROR(__xludf.DUMMYFUNCTION("ROUNDUP( ( SUM( INDIRECT( ""F""&(ROW()+1)&"":F""& IFERROR( INDEX( FILTER( ROW(A:A), REGEXMATCH(A:A, ""^[•◆■※⊳]""), ROW(A:A) > ROW() ), 1 "&" )-1, 999 ) ) )+ SUM( INDIRECT( ""G""&(ROW()+1)&"":G""& IFERROR( INDEX( FILTER( ROW(A:A), REGEXMATCH(A:A, ""^[•◆■※⊳]""), ROW(A:A) "&"> ROW() ), 1 )-1, 999 ) ) ) )/2 )"),36.0) -> 36 | H21: Standard
B22: Form Strategy & Lead Capture Optimization | C22: ForceBrands needs a form strategy that leverages HubSpot forms to optimize lead capture and scoring across their new website. | D22: A8 to advise on form architecture, required properties, and smart content opportunities to support compatibility with lead scoring and lead routing requirements. | E22: A8 to consult on best practices for: - Lead-score dependent properties and page tracking - Hidden field mapping for attribution - Form strategy to support analytics and conversion tracking - Assumes 5 to 6 form types and membership log-in does introduce lifecycle complexities - ForceBrands and web vendor to implement new forms according to aligned project plan. Website Note: This service and component has a critical web project dependency | F22: 4 | G22: 6 | I22: Consulting
B23: Update and Optimize Contact and Account Lifecycles | C23: ForceBrands needs a centralized lifecycle that accommodates their marketing and sales process to ensure they are nurtured appropriately. | D23: A8 to support and consult on a "master" lifecycle stage aligned with ForceBrands's marketing and sales process, with established transition criteria between stages, and recommend automation rules to move contacts through the lifecycle based on engagement and qualification thresholds. | E23: - Single lifecycle per person and account objects - Candidate records to be segmented by a contact type property to create separation from client records - Lifecycle automation may need to be integrated with lead scoring models - Custom lead scoring will support this strategy and will be implemented within its own service line - These hours represent hybrid working sessions and consulting to effectively utilize budget for launch Website Note: This service and component has a critical web project dependency | F23: 8 | G23: 10 | I23: Consulting
B24: Update and Optimize a New Lead Scoring Model | C24: ForceBrands needs a lead scoring model that identifies both client prospects and high-value candidates for their recruiting business. | D24: A8 to consult ForceBrands on HubSpot's new lead scoring functionality that accounts for lead and account engagement. | E24: - Forcebrands to use new native scoring tools - Dual scoring model for clients vs candidates - Behavioral scoring based on website engagement - Threshold definition for MQL handoff to sales to be defined in discovery phase - These hours represent hybrid working sessions and consulting to effectively utilize budget for launch, A8 to review relevent assets and update as required Website Note: This service and component has a critical web project dependency | F24: 8 | G24: 10 | I24: Consulting
B25: Marketing-to-Sales Lead Assignment Automation | C25: ForceBrands needs automated workflows to route qualified leads from marketing to the appropriate sales team member based on territory, search type, and lead score. | D25: A8 to build lead routing workflows that consider multiple criteria including geography, industry vertical, search type (contingency vs retained), and lead score thresholds. | E25: Dynamic lead assignment based on defined criteria - Industry Expertise (First Tier) - Geography (Second Tier) - Existing account ownership to factor into assignment criteria - Automated notifications and task creation - SLA tracking between marketing and sales - Feedback loop for lead quality monitoring | F25: 12 | G25: 14 | I25: Consulting
A27: • | B27: HubSpot Implementation - Sales Hub: Implement HubSpot Sales Hub that aligns with ForceBrands's processes and data needs. | F27: =IFERROR(__xludf.DUMMYFUNCTION("ROUNDUP( ( SUM( INDIRECT( ""F""&(ROW()+1)&"":F""& IFERROR( INDEX( FILTER( ROW(A:A), REGEXMATCH(A:A, ""^[•◆■※⊳]""), ROW(A:A) > ROW() ), 1 "&" )-1, 999 ) ) )+ SUM( INDIRECT( ""G""&(ROW()+1)&"":G""& IFERROR( INDEX( FILTER( ROW(A:A), REGEXMATCH(A:A, ""^[•◆■※⊳]""), ROW(A:A) "&"> ROW() ), 1 )-1, 999 ) ) ) )/2 )"),41.0) -> 41 | H27: Standard
B28: User Permissions & Team Structure | C28: ForceBrands needs role-based permissions that support their newly migrated sales team structure while protecting client data across teams. | D28: A8 to host a working session and advise and consult on team hierarchies, permission sets, and record access rules that align with ForceBrands' organizational structure and data requirements. | E28: - ForceBrands to own implementation and configuration, A8 to guide and consult on this process to leverage budget effectively Team set-up includes: - Set up permission sets for sales, recruiting, and marketing roles - Implement record-level permissions for sensitive revenue or commission data - Deal/pipeline visibility rules - ForceBrands is anticipating approximately 20-30 new users in Phase 1 | F28: 2 | G28: 2 | I28: Consulting
B29: Customize Record Layouts | C29: ForceBrands wants to show the right information to the right people at the right time on the right object so their users can have a simpler process to follow in their portal. | D29: A8 to host a working session and advise and consult to support Forcebrand's self-implementation of these updates. | E29: - A8 to train on the left, center, and right sidebar customization capabilities - Contact, Company, Deal, and custom object record customizations - A8 to train on the relationship between views and team assignments - A8 to highlight settings within deal pipeline/cards - A8 recommends a single CRM admin or clear responsibilities between Marketing and Sales team | F29: 2 | G29: 2 | I29: Consulting
B30: Sales Account + Contact Management | C30: Forcebrands needs a stronger feedback loop between marketing and sales to support their segmentation, reporting, and process needs. Additionally, for existing clients, ownership rules need to support lead assignment automations. | D30: A8 to implement and configure foundational automations to support record ownership and feedback data points between sales and marketing. | E30: - Assumes 4 to 5 automations to support data transfers between records - Opportunity for working sessions and consulting to preserve budget - Anticipating the use of Contacts, Companies, and Deals to keep reporting and segmentation easier to maintain and more scalable. Required data points and configuration include: - Account + contact ownership - Feedback loop back to marketing - DQ Reasons at contact and account level | F30: 6 | G30: 8 | I30: Consulting
B31: Sales Pipeline Configuration | C31: ForceBrands needs customized sales pipelines to manage their distinct contingency and retained search processes with appropriate automation and stage requirements. | D31: A8 to build and configure one pipeline with deal stages and required fields that reflect ForceBrands' recruiting sales methodology. | E31: - At launch, Forcebrands is assuming one pipeline will be sufficient to capture their sales process and revenue data - If additional pipelines are required to process or forecasting requirements, ForceBrands to implement additional pipelines with A8's consultative support - Configure stage properties per defined exit/entry criteria - Forcebrands to implement automations with A8 support per other consulting line items ForceBrands is leveraging the following business lines: Search - for full-time direct hire searches Temporary services - for fractional or hourly-based work Advisory - for project-based, milestone, deliverable-based work Note: Pipelines must be determined early to support sync logic and filtering | F31: 6 | G31: 8 | I31: Consulting
B32: Custom Deal/Search Fee & Commission Tracking | C32: ForceBrands needs deal automation to support their fee structures and commission calculations for both contingency and retained search models. | D32: A8 to implement search fee calculations, and commission tracking workflows that accommodate different search types and split placement scenarios. | E32: - Deal amount strategy to be defined and approved during the Solution Engineering Phase before implementation - Pre-placement deals may need to use a specific "proxy" property. Deal amount can be overwritten, but implications within reporting will be defined during the Solution Engineering Phase - Automated fee calculation based on placement salary and Bullhorn Data - Commission tracking for individual recruiters done via calculated properties | F32: 6 | G32: 8 | I32: Consulting
B33: Sales Task Management / Sales Enablement Consulting | C33: ForceBrands needs their sales team to leverage the enablement tools in HubSpot to reduce spending time on administrative tasks and data input. | D33: A8 to consult within working sessions to support Forcebrands' self-implementation of: - Sales Workspace - Calendar, Email, and Conferencing Connectors - Task automations - Sales Sequences | E33: - A8 to assume a consulatative role to effectively leverage budget and support the launch process - Working sessions may include building the framework of a sequence and deal-based automations to support the lead management and sales process | F33: 6 | G33: 8 | I33: Consulting
B34: Sales Quoting + Contracting Consulting | C34: ForceBrands to send their clients documents and agreements throughout the sales process, at intake, and after a placement has been made. | E34: - A8 to assume a hybrid consulatative and implementation role to effectively leverage budget and support the launch process - ForceBrands will need to review Docusign's documentation during the project - HubSpot quotes have been evaluated as an unlikely solution due to line item and revenue limitations ForceBrands has an existing three-phase contract workflow for most of their sold searches: - Main Service Agreement (MSA) - Umbrella agreement establishing the client relationship - Statement of Work (SOW) - Job-specific details including title, estimated fee percentage, and billing terms - Email Confirmation - Post-placement confirmation with final fee calculations and start date Note: Docusign does not handle multiple envelope to single deal relationships via the native integration. It may be able to be used as a front-end to create a new document, but it will likely NOT sync to the deal correctly and may also not pull in token data. Native integration documentation is available here Additional solutions, like Portant, can be explored during a Phase 2 | F34: 8 | G34: 10 | I34: Consulting
A36: • | B36: HubSpot Consulting - Content Hub: Support the holistic project with website consulting to ForceBrands and additional vendor | F36: =IFERROR(__xludf.DUMMYFUNCTION("ROUNDUP( ( SUM( INDIRECT( ""F""&(ROW()+1)&"":F""& IFERROR( INDEX( FILTER( ROW(A:A), REGEXMATCH(A:A, ""^[•◆■※⊳]""), ROW(A:A) > ROW() ), 1 "&" )-1, 999 ) ) )+ SUM( INDIRECT( ""G""&(ROW()+1)&"":G""& IFERROR( INDEX( FILTER( ROW(A:A), REGEXMATCH(A:A, ""^[•◆■※⊳]""), ROW(A:A) "&"> ROW() ), 1 )-1, 999 ) ) ) )/2 )"),10.0) -> 10 | H36: High
B37: Website Migration Project Coordination | C37: ForceBrands needs A8 to coordinate with New Breed on the website redesign project to ensure proper tracking, form strategy, and lead capture alignment with HubSpot configuration. | D37: A8 to participate in limited coordination meetings with New Breed and ForceBrands, providing direction for tracking codes, form handling, and lead scoring requirements on the new website. | E37: - Coordination meetings with New Breed will be scheduled ad hoc and as capacity allows - ForceBrands to attend all meetings Web dependencies include: - Form strategy alignment and requirements - Tracking code and analytics setup guidance - Lead scoring implementation | F37: 10 | G37: 10 | I37: Project Management
A39: • | B39: Data Migration: Migrate Bullhorn entity / object data into HubSpot to support lead and account management | F39: =IFERROR(__xludf.DUMMYFUNCTION("ROUNDUP( ( SUM( INDIRECT( ""F""&(ROW()+1)&"":F""& IFERROR( INDEX( FILTER( ROW(A:A), REGEXMATCH(A:A, ""^[•◆■※⊳]""), ROW(A:A) > ROW() ), 1 "&" )-1, 999 ) ) )+ SUM( INDIRECT( ""G""&(ROW()+1)&"":G""& IFERROR( INDEX( FILTER( ROW(A:A), REGEXMATCH(A:A, ""^[•◆■※⊳]""), ROW(A:A) "&"> ROW() ), 1 )-1, 999 ) ) ) )/2 )"),32.0) -> 32 | H39: High
B40: Contact & Company/Account Delta Data Migration | C40: ForceBrands needs their active contact and company records migrated from Bullhorn to establish their database before the sales team transitions to HubSpot. | D40: A8 to consult on required Bullhorn export and import startegy to align with existing data and Phase 1 needs. A8 to advise on linking data points to preserve associations and reduce duplicates. | E40: - ForceBrands will clean and transform export files in an agreed format - A8 to provide templates and transformation guidance, dependant on integration strategy - A8 will support with mapping and import strategy but cannot guarantee data quality - Field-level information will be migrated. Historical sales activity is not part of this Phase 1 scope - Test imports can occur in ForceBrands's sandbox instance - Data quality issues requiring additional A8 support will be addressed via a change order - A8 will assist with one round of field-level mapping QA. Issues beyond template compliance or requiring multiple revisions may require a change order | F40: 6 | G40: 8 | I40: Consulting
B41: Active Deal & Pipeline Data Migration + Backfill | C41: ForceBrands needs their in-flight recruiting searches migrated to HubSpot to ensure business continuity when sales team transitions from Bullhorn. | D41: A8 to migrate active contingency and retained searches, mapping Bullhorn job records to HubSpot deals with appropriate pipeline stages and property values. | E41: - Historical criteria to be defined during the Disocvery and Solution Engineering Phases - To support launch, backfill to also focus on open searches and recent placements only - Map job status to appropriate pipeline stages - Include fee structures and candidate associations - Coordinate timing with sales team training - Manual validation of high-value searches post-migration | F41: 20 | G41: 30 | I41: Development
A43: • | B43: Bullhorn ATS <> HubSpot System Integration: Develop a custom data connector between Bullhorn and HubSpot | F43: =IFERROR(__xludf.DUMMYFUNCTION("ROUNDUP( ( SUM( INDIRECT( ""F""&(ROW()+1)&"":F""& IFERROR( INDEX( FILTER( ROW(A:A), REGEXMATCH(A:A, ""^[•◆■※⊳]""), ROW(A:A) > ROW() ), 1 "&" )-1, 999 ) ) )+ SUM( INDIRECT( ""G""&(ROW()+1)&"":G""& IFERROR( INDEX( FILTER( ROW(A:A), REGEXMATCH(A:A, ""^[•◆■※⊳]""), ROW(A:A) "&"> ROW() ), 1 )-1, 999 ) ) ) )/2 )"),189.0) -> 189 | H43: High
B44: Bullhorn Integration Requirements Document | C44: ForceBrands requires that their integration requirements are clearly defined before starting on development so that success criteria and the approach are clear. Additionally, both A8 and ForceBrands requires thorough documentation to support maintenance and updates to the solution. | D44: A8 to create technical design documentation outlining integration architecture, data flow rules, and code environment considerations for the custom Bullhorn connector. | E44: - Aptitude 8 will create an integration requirements document to represent the integration logic and where code is stored - Design integration architecture using HubSpot, Pipedream, and Bullhorn ATS - Document field mappings for all elligible objects - Define sync rules and conflict resolution logic - Compliment plan for initial data migration vs ongoing synchronization - Define which records need to sync on a regular schedule (eg. Deals + Opportunities) versus a nightly batch (eg. Placements) - A8 to document any implementation dependencies between objects eg. HubSpot workflows that need to be created to support sync criteria | F44: 10 | G44: 12 | I44: Solutions Engineering
B45: Integration Infrastructure Development + Set-up | C45: ForceBrands needs a robust custom integration to replace the native Bullhorn connector with bi-directional synchronization of contacts, companies, jobs, and placements. | D45: A8 to establish the integration enviornment in Pipedream and connect to Sandbox instances of HubSpot and Bullhorn. | E45: - A8 will use Pipedream to store integration logic and faciliate the data transfer. ForceBrands will be required to create and own their own instance, and then allow A8 to develop code. - If ForceBrands need a Pipedream monthly cost estimate — we’ll need the record volume estimates. We do, however, anticipate a cost savings compared to Linkfuse - Development contingent on A8 being an approved Bullhorn App Partner - A8 to leverage Bullhorn Sandbox + HubSpot Sandbox for inital connection and testing - Bullhorn Sandbox Documentation | F45: 18 | G45: 20 | I45: Development
B46: Custom Objects & Foundational Properties Setup | C46: ForceBrands needs HubSpot configured to support their recruiting business model with custom properties for jobs, placements, and specialized contact types. | D46: A8 to configure custom properties and custom objects to track recruiting-specific data like candidate skills, job requirements, placement history, and commission structures. | E46: - Up to two custom objects (Placements + Jobs) - A8 to create up to 10 custom properties across all objects - A8 to support data mapping exercise with ForceBrands with a template via the 'Data Migration Strategy & Data Mapping' service line above. - ForceBrands to implement all properties (A8 will evaluate other property creation tools to faciliate faster creation) | F46: 3 | G46: 4 | I46: Solutions Engineering
B47: Sync Records from HubSpot TO Bullhorn | C47: ForceBrands needs to send account and deal information from HubSpot into Bullhorn to faciliate the sales-to-service process with the recruiter team. | D47: A8 to develop a custom integration between HubSpot and Bullhorn ATS, leveraging Pipedream to support the code and logic. | E47: - A8 to support Bi-directional field mapping configuration where applicable - Assuming custom field support for both platforms - Assuming a max of 50 fields per object across Contacts, Companies, Deals, and Custom Objects Records syncing TO Bullhorn include: - HS Contacts > clientContacts - HS Contacts > Candidates - HS Companies > clientCorporations - HS Deals > Opportunities - HS Notes > Notes Integration Notes: - If there is overlap of jane@gmail.com as BOTH client contact and candidate — we’ll have to have special rules of which record “wins” on specific fields and flatten and simplify - Assumption is that Bullhorn automation continues to transfer/transform Opportunity to Job, but retains Opportunity ID - We assume that the opportunity does not also exist as converted, closed, or closed won AFTER conversion - Notes can only associate to accounts and contacts in Bullhorn, not opportunities Not Syncing in Phase 1: - Contacts > Leads - For launch and to simplify their sales process, ForceBrands is not using a lead object - Deals < Placement Commissions - we’ll do estimate commissions on the deal object directly, today, ForceBrands use this object as a holding record and do calculations externally | F47: 45 | G47: 60 | I47: Solutions Engineering
B48: Sync Records from Bullhorn TO HubSpot | C48: ForceBrands needs to send account and deal information from Bullhorn intoHubSpot to faciliate the placement and fee revenue logic on sold deals. Along with being able to target and segment candidates. | D48: A8 to develop a custom integration between HubSpot and Bullhorn ATS, leveraging Pipedream to support the code and logic. | E48: Records syncing TO HubSpot include: - clientContacts > HS Contacts - Candidates > HS Contacts - clientCorporations > HS Companies - Opportunities > HS Deals - Job Orders > HS Custom Object - Placements > HS Deals or Custom Object Critical Data Note: To support the revenut and placement data correctly, one deal in HubSpot must represent one job in Bullhorn. Note: We are not anticipating a need to sync Notes from Bullhorn to HubSpot for Phase 1 | F48: 45 | G48: 60 | I48: Solutions Engineering
...

Sheet Change Order
C1: ForceBrands Master Customer Story
B2: Service | C2: Customer Story | D2: Suggested Path | E2: Assumptions | F2: Estimated Low Hours | G2: Estimated High Hours | H2: Potential Variance | I2: Function | J2: POC
B4: Executive Summary | E4: Additional Notes + Considerations
A7: • | B7: HubSpot Implementation - Sales Hub: Implement HubSpot Sales Hub that aligns with ForceBrands's processes and data needs. | F7: =IFERROR(__xludf.DUMMYFUNCTION("ROUNDUP( ( SUM( INDIRECT( ""F""&(ROW()+1)&"":F""& IFERROR( INDEX( FILTER( ROW(A:A), REGEXMATCH(A:A, ""^[•◆■※⊳]""), ROW(A:A) > ROW() ), 1 "&" )-1, 999 ) ) )+ SUM( INDIRECT( ""G""&(ROW()+1)&"":G""& IFERROR( INDEX( FILTER( ROW(A:A), REGEXMATCH(A:A, ""^[•◆■※⊳]""), ROW(A:A) "&"> ROW() ), 1 )-1, 999 ) ) ) )/2 )"),50.0) -> 50 | H7: Standard
B8: Platform Integration | C8: ForceBrands will install and set up various platform integrations with HubSpot to support sales and marketing processes using native integrations/workflows including Slack, Calendly & potentially LinkedIn. A8 to consult on implementation and optimization. | D8: A8 to consult with ForceBrands on how to best use HubSpot’s native integrations with Slack, HubSpot scheduling tools, and LinkedIn. Our focus will be on aligning these tools to sales & marketing processes, recommending best practices, and advising on adoption and governance so the team can implement effectively. | E8: - Up to 3 workshops focusing on integration objectives and UI optimization - Provide automation recommendations, configure 2-3 workflows. | F8: 6 | G8: 12 | I8: Consulting | J8: Matt Scaramastra/Jen O'Connell
B9: Pipeline Automation | C9: ForceBrands needs advanced automation implemented so that specified activities in Bullhorn or Docusign trigger deal or lifecycle stage advancement and to fulfill optimal lead routing/assignment rules. | D9: Sales Qualification → Lifecycle Advancement - Establish rules where a designated sales qualifying call meeting type automatically triggers advancement of the contact to SQL lifecycle stage. Contract Progression → Deal Stage Update - Set up automation for deal stages to advance when key contract milestones are reached (e.g., MSA sent or signature completed on a DocuSign envelope associated with the deal). - Ops Hub Pro will not be an option for any custom coded workflows, which may limit automation around Docusign. | E9: Note: Ops Hub costs would be separate and are not included in scope but not expected as prerequisite at this time. | F9: 12 | G9: 18 | I9: Development | J9: Matt Scaramastra/Jen O'Connell
B10: Data Transformation | C10: ForceBrands needs company industry to be set from a list of prescribed options. When HubSpot enriches company records' industry value, a workflow should update the industry to one of the prescribed values. | D10: Build a standardized UI workflow that leverages a ForceBrands industry picklist. This ensures consistent classification of records across key categories such as: - Agency - Alch Bev - Beauty - Cannabis - Consumer Tech - Food - Non-Alch Beverage - PE/VC - Pet | E10: - ForceBrands Hubspot Breeze Enrichment Taxonomy | F10: 3 | G10: 6 | I10: Consulting | J10: Matt Scaramastra/Jen O'Connell
B11: Lead Scoring | C11: The integration between the Niceboard job board platform and HubSpot is a critical component of ForceBrands' lead management and scoring strategy, particularly for capturing high-intent client prospects and high-value candidates. While A8 is not responsible for the Zapier build, the workflows in HubSpot are essential for processing the data and applying the lead scoring logic defined in the discovery. | D11: A8 to consult with ForceBrands in 2-3 workshop sessions on the processes that ingest Niceboard data and automatically set Contact Type (Client/Candidate), update the lead scores, and drive lead score triggered workflows for lifecycle stage, integration, etc. This is a strategy and recommendation deliverable. | E11: - Up to 2-3 workshops focusing on feasibility, integration optimization, and workflow strategies. - Evaluate NiceBoard/Zapier integration, provide integration and automation recommendations, configure 2-3 workflows. | F11: 8 | G11: 10 | I11: Strategy | J11: Matt Scaramastra/Jen O'Connell
B12: Contact/Company Record Enrichment | C12: ForceBrands wants to implement Breeze for contact & company enrichment to replace Zoom Info. | D12: Help guide evaluation of Breeze as the new enrichment tool for contacts and companies, potentially replacing ZoomInfo. Support optimization of Breeze or Zoominfo, testing enrichment accuracy across ForceBrands’ core data objects, establishing governance to ensure ongoing data quality and consistency, and optimization of segmentation and related workflows. | E12: Breeze/Zoominfo will be configured only for Contact and Company enrichment (not Deals, custom objects, or custom API enrichments). - Up to 2 workshops focusing on feasibility, optimization, and workflow strategies. - Development of up to 3 workflows and related lists/views to support segmentation and automation. | F12: 10 | G12: 14 | I12: Strategy | J12: Colleen Ogg
A13: • | B13: Data Migration: Migrate Bullhorn entity / object data into HubSpot to support lead and account management | F13: =IFERROR(__xludf.DUMMYFUNCTION("ROUNDUP( ( SUM( INDIRECT( ""F""&(ROW()+1)&"":F""& IFERROR( INDEX( FILTER( ROW(A:A), REGEXMATCH(A:A, ""^[•◆■※⊳]""), ROW(A:A) > ROW() ), 1 "&" )-1, 999 ) ) )+ SUM( INDIRECT( ""G""&(ROW()+1)&"":G""& IFERROR( INDEX( FILTER( ROW(A:A), REGEXMATCH(A:A, ""^[•◆■※⊳]""), ROW(A:A) "&"> ROW() ), 1 )-1, 999 ) ) ) )/2 )"),24.0) -> 24 | H13: High
B14: Marketing Contact Segmentation | C14: Lists should be created based on content interaction, page visits, and other behavioral triggers for targeted campaigns. The DNR (Do Not Recruit) list from Metabase should be recreated in HubSpot to prevent recruiters from poaching candidates from active clients. The system should manage contacts who change companies while maintaining associations between old and new contact records. | D14: A8 to host workshops with ForceBrands' sales teams and leadership to understand objectives, data architecture, and to provide training on advanced filtering options. | E14: - Up to 3-4 workshops focusing on segmentation objectives and optimal filtering - Review of lists, and DNR Metabase configuration - Contact object/association and view customization to utilize DNR status - Contact object/association and view customization to capture employment history/current association status - ForceBrands to ensure all relevant stakeholders are available and support scheduling | F14: 8 | G14: 12 | I14: Consulting | J14: Matt Scaramastra/Jen O'Connell
B15: Sales Process/Asset Migration | C15: ForceBrands needs Tearsheets recreated as 1) active lists and 2) as a marketing event or custom object to enable the association of various objects (Contacts, companies, deals, etc). | D15: A8 to evaluate current use cases and collaborate with ForceBrands to prioritize active lists and implement optimal functionality to enable show/event Tearsheet use case. | E15: - Review list filter configuration in Bullhorn and ensure property/logic is configured in HubSpot. - Setup Tearsheet saved searches as active lists/segments (up to 60) - Setup Marketing Events/Custom Objects - Export & Import up to 20 historical event attendees/associates to HubSpot Object | F15: 12 | G15: 16 | I15: Consulting | J15: Matt Scaramastra/Jen O'Connell
A16: • | B16: Bullhorn ATS <> HubSpot System Integration: Develop a custom data connector between Bullhorn and HubSpot | F16: =(sum(F17:F19)+sum(G17:G19))/2 -> 52.5 | H16: Standard
B17: Sync Records from HubSpot TO Bullhorn | C17: ForceBrands needs to send account and deal information from HubSpot into Bullhorn to faciliate the sales-to-service process with the recruiter team. | D17: A8 to develop a custom integration between HubSpot and Bullhorn ATS, leveraging Pipedream to support the code and logic. | E17: - A8 to support Bi-directional field mapping configuration where applicable - Assuming custom field support for both platforms - Assuming a max of 50 fields per object across Contacts, Companies, Deals, and Custom Objects Records syncing TO Bullhorn include: - HS Contacts > clientContacts - HS Contacts > Candidates - HS Companies > clientCorporations - HS Deals > Opportunities - HS Notes > Notes - HS Meetings > BH Notes - HS Calls > BH Notes Integration Notes: If there is overlap of jane@gmail.com as BOTH client contact and candidate — we’ll have to have special rules of which record “wins” on specific fields and flatten and simplify Candidate and client specific fields do not overlap. Fields that do overlap are standard such as first name, last name, email address. - Candidate contacts and client contacts that share the same email address will exist as a single contact record in HubSpot. - Assumption is that Bullhorn automation continues to transfer/transform Opportunity to Job, but retains Opportunity ID - We assume that the opportunity does not also exist as converted, closed, or closed won AFTER conversion - Notes can only associate to accounts and contacts in Bullhorn, not opportunities Not Syncing in Phase 1: - Contacts > Leads - For launch and to simplify their sales process, ForceBrands is not using a lead object - Deals < Placement Commissions - we’ll do estimate commissions on the deal object directly, today, ForceBrands use this object as a holding record and do calculations externally" ------- | F17: 15 | G17: 20 | I17: Development | J17: Michelle Tabor
B18: Sync Records from Bullhorn TO HubSpot | C18: ForceBrands needs to send account and deal information from Bullhorn intoHubSpot to faciliate the placement and fee revenue logic on sold deals. Along with being able to target and segment candidates. | D18: A8 to develop a custom integration between HubSpot and Bullhorn ATS, leveraging Pipedream to support the code and logic. | E18: Records syncing TO HubSpot include: - clientContacts > HS Contacts - Candidates > HS Contacts - clientCorporations > HS Companies - Opportunities > HS Deals - Job Orders > HS Deals - Placements > HS Custom Objects - BH Notes > HS Meetings 6-10 - BH Notes > HS Calls 6-10 - BH Notes > HS Notes 6-10 Note: We are not anticipating a need to sync Notes from Bullhorn to HubSpot for Phase 1 | F18: 15 | G18: 20
B19: Integration Testing & Deployment (UAT) | C19: ForceBrands needs comprehensive testing and a controlled deployment process to ensure the custom integration operates reliably in production without data loss or conflicts. | D19: A8 to conduct thorough integration testing within defined UAT scenarios, followed by a phased production deployment with monitoring. | E19: - A8 to complete internal testing for all sync functions before transitioning UAT to ForceBrands for approvals - A8 to to confirm integration capabilities with production-like volumes - A8 + ForceBrands to complete UAT in both Sandbox and production before go-live | F19: 15 | G19: 20
A20: ◆ | B20: Project Management + Strategy: Support this project with transparency and regular progress reports | F20: 30 | H20: Standard | I20: Project Management
B21: Project Administration | C21: ForceBrands needs a partner to support managing the HubSpot CRM and Integration project, ensuring deadlines are clear and met. | D21: To support management and communication, a project manager and delivery lead will own all A8 tasks and clearly communicate needs to ForceBrands. | E21: - Assumption is that website vendor will provide regular updates async to reduce regular meetings. Hours can be pulled from 'HubSpot Consulting - Content Hub' Workstream as meetings are required - Visibility to budget spend will be provided during the duration of the project - A8 will provide check-in agenda items and follow-ups - ForceBrands to communicate to A8's shared inbox for easier collaboration and timely responses - Standard 25-30% calculation based on scoped hours Note: A8 will not be responsible for actively updating tasks or communications in any other PM/PSA platforms per this contract and budget | F21: 30 | G21: 30
E24: Total Estimated Engagement Hours: | F24: =sum(I24+I25)/2 -> 156 | H24: Low Hour Estimate: | I24: =sum(F21,F17:F19,F14:F15,F8:F12) -> 134
H25: High Hour Estimate: | I25: =sum(G21,G17:G19,G14:G15,G8:G12) -> 178
E26: Total Estimated Investment:
I37: `

Sheet Details
D1: Proposal + Project Details | G1: [Company] aims to enhance their CRM functionality by integrating HubSpot with key business systems like QuickBooks and Power BI, streamlining financial management and analytical reporting. They prioritize automation of sales pipelines and customization of quotes to improve operational efficiency and customer engagement. A strategic partnership is sought for long-term optimization and scalability of their CRM ecosystem. [Company] end goal is a cohesive, data-driven environment that supports growth and adapts to evolving business needs.
A2: • | B2: Deal Inputs | F2: Deal + Asset Links
B3: Company Name | C3: ForceBrands | F3: Google Folder | G3: https://drive.google.com/drive/folders/14fDmynzdEigsuU_KtYA9DFUixVnMCVet
B4: Deal Record ID | C4: 35110324900 | F4: Deal Link
B5: Last Sync to HubSpot | C5: 45828.27 | F5: Solutions Architect
B6: Request Scope Review | D6: scoping_status | F6: Service Library Message
B7: Scope Reviewed | D7: scoped_reviewed
B9: Engagement Inputs
B10: NOW Project
B11: Hourly Project Rate | C11: 237 | D11: project_hourly_rate
B12: Project Management Factor | C12: 0.2
B13: SA Expected Start Date | C13: 45852
B14: Total Project Months | C14: 5 | D14: project_duration
B15: SA Expected End Date | C15: =C13+(C14*30) -> 46002
B17: NEXT Retainer
B18: Hourly NEXT Retainer Rate | C18: 237 | D18: retainer_hourly_rate
B19: NEXT Hours Per Month | C19: 30 | D19: retainer_hours_per_month_sold
B20: NEXT Retainer Months | C20: 1 | D20: retainer_months_sold
B23: Calculated Project Details | F23: Calculated Ranges | G23: Low Hours | H23: High Hours
B24: Deal Amount | C24: {=INDEX(Overview!F:G, MATCH("⚑", Overview!A:A, 0), 1)} -> 139830 | D24: amount | F24: Project/Service Estimates: | G24: =IFERROR(__xludf.DUMMYFUNCTION("ARRAYFORMULA( SUMIFS( Overview!F:F, Overview!F:F, "">0"", Overview!A:A, ""<>•*"", Overview!A:A, ""<>◆*"", ROW(Overview!A:A), "">""&MIN(IF(REGEXMATCH(Overview!A:A,""^•""),ROW(Overview!A:A))), ROW(Overview!A:A), ""<""&MIN(IF(REGEX"&"MATCH(Overview!A:A,""^※|^◆""),ROW(Overview!A:A),99999)) ) )"),412.0) -> 412 | H24: =IFERROR(__xludf.DUMMYFUNCTION("ARRAYFORMULA( SUMIFS( Overview!G:G, Overview!G:G, "">0"", Overview!A:A, ""<>•*"", Overview!A:A, ""<>◆*"", ROW(Overview!A:A), "">""&MIN(IF(REGEXMATCH(Overview!A:A,""^•""),ROW(Overview!A:A))), ROW(Overview!A:A), ""<""&MIN(IF(REGEX"&"MATCH(Overview!A:A,""^◆""),ROW(Overview!A:A),99999)) ) )"),517.0) -> 517
B25: Total Engagement Hours Sold | C25: =SUMIFS(Overview!F:F, Overview!A:A, "*•*") + SUMIFS(Overview!F:F, Overview!A:A, "*◆*") + SUMIFS(Overview!F:F, Overview!A:A, "*■*") -> 590 | D25: sold_hours | F25: Project Management: | G25: =G24 * C12 -> 82.4 | H25: =H24 * C12 -> 103.4
B26: Total Project Hours Sold | C26: =SUMIFS(Overview!F:F, Overview!A:A, "*•*") + SUMIFS(Overview!F:F, Overview!A:A, "*◆*") -> 560 | D26: project_hours_sold | F26: Post-Project Support: | G26: {=INDEX(Overview!F:G, MATCH("■*", Overview!A:A, 0), 1)} -> 30 | H26: {=INDEX(Overview!F:G, MATCH("■*", Overview!A:A, 0), 1)} -> 30
B27: Total Retainer Hours Sold | C27: =SUMIFS(Overview!F:F, Overview!A:A, "*■*") -> 30 | F27: Hour Estimates: | G27: =SUM(G24:G26) -> 524.4 | H27: =SUM(H24:H26) -> 650.4
B28: Expected End Date | C28: =EDATE(C13, C14) -> 46005 | F28: Investment Ranges: | G28: =G27*C11 -> 124282.8 | H28: =H27*C11 -> 154144.8
B29: Expected Project Hours/Month | C29: =roundup(C26/C14,0) -> 112
B30: Linear Expected Project Hours/Week | C30: =roundup(C29/4.3,0) -> 27 | F30: Total Estimated Engagement Hours: | G30: =SUMIFS(Overview!F:F, Overview!A:A, "*•*") + SUMIFS(Overview!F:F, Overview!A:A, "*◆*") + SUMIFS(Overview!F:F, Overview!A:A, "*■*") -> 590
B31: Peak Project Expected Hours | C31: =C30*1.2 -> 32.4 | F31: Total Estimated Investment: | G31: {=INDEX(Overview!F:G, MATCH("⚑", Overview!A:A, 0), 1)} -> 139830
B32: Low Project Expected Hours | C32: =C30*0.5 -> 13.5
B33: Dev Work Percentage | C33: =C40/C45 -> 0.16830797 | D33: dev_work_pct
B34: SE Work Percentage | C34: =C42/C45 -> 0.29364369 | D34: se_work_pct
A37: ※ | B37: Calculated Function Summary | F37: SOW Summarized Line Items
B38: =IFERROR(__xludf.DUMMYFUNCTION("LET( square_row, MATCH(""■"", Overview!A:A, 0) - 1, valid_range, SEQUENCE(square_row), raw_calcs, QUERY( ARRAYFORMULA({ IF(INDIRECT(""Overview!I1:I""&square_row) = """", ""Unassigned"", INDIRECT(""Overview!I1:I""&square_row)), IF( "&" REGEXMATCH(INDIRECT(""Overview!A1:A""&square_row), ""•""), 0, IF( REGEXMATCH(INDIRECT(""Overview!A1:A""&square_row), ""◆""), INDIRECT(""Overview!F1:F""&square_row), (INDIRECT(""Overview!F1:F""&square_row"&") + INDIRECT(""Overview!G1:G""&square_row))/2 ) ) }), ""select Col1, sum(Col2) where Col1 is not null and Col2 is not null group by Col1 label Col1 'Function', sum(Col2) 'Hours'"", 0 ), functions, {""F"&"unction"", ""Hours""; ""Consulting"", IFERROR(VLOOKUP(""Consulting"", raw_calcs, 2, FALSE), 0); ""Development"", IFERROR(VLOOKUP(""Development"", raw_calcs, 2, FALSE), 0); ""Project Management"", IFERROR(VLOOKUP("&"""Project Management"", raw_calcs, 2, FALSE), 0); ""Solutions Engineering"", IFERROR(VLOOKUP(""Solutions Engineering"", raw_calcs, 2, FALSE), 0); ""Strategy"", IFERROR(VLOOKUP(""Strategy"", raw_calcs, 2, FALSE), 0); "&" ""Unassigned"", IFERROR(VLOOKUP(""Unassigned"", raw_calcs, 2, FALSE), 0)}, functions )"),"Function") -> Function | C38: =IFERROR(__xludf.DUMMYFUNCTION("""COMPUTED_VALUE"""),"Hours") -> Hours | D38: Percent of | F38: =IFERROR(__xludf.DUMMYFUNCTION("QUERY( Overview!A7:F99, ""select B, F where (A = '•' or A = '◆' or A = '■') and B is not null"" )"),"Discovery + Requirements Gathering: Gather and document ForceBrand's business + project requirements") -> Discovery + Requirements Gathering: Gather and document ForceBrand's business + project requirements | G38: =IFERROR(__xludf.DUMMYFUNCTION("""COMPUTED_VALUE"""),65.0) -> 65 | H38: =G38*C11 -> 15405
B39: =IFERROR(__xludf.DUMMYFUNCTION("""COMPUTED_VALUE"""),"Consulting") -> Consulting | C39: =IFERROR(__xludf.DUMMYFUNCTION("""COMPUTED_VALUE"""),143.0) -> 143 | D39: =C39/$C$45 -> 0.25604297 | F39: =IFERROR(__xludf.DUMMYFUNCTION("""COMPUTED_VALUE"""),"Solutions Engineering / Project Planning / Final Scope Validation: Define and design a HubSpot instance to meet ForceBrand's needs") -> Solutions Engineering / Project Planning / Final Scope Validation: Define and design a HubSpot instance to meet ForceBrand's needs | G39: =IFERROR(__xludf.DUMMYFUNCTION("""COMPUTED_VALUE"""),34.0) -> 34 | H39: =G39*C11 -> 8058
B40: =IFERROR(__xludf.DUMMYFUNCTION("""COMPUTED_VALUE"""),"Development") -> Development | C40: =IFERROR(__xludf.DUMMYFUNCTION("""COMPUTED_VALUE"""),94.0) -> 94 | D40: =C40/$C$45 -> 0.16830797 | F40: =IFERROR(__xludf.DUMMYFUNCTION("""COMPUTED_VALUE"""),"HubSpot Implementation - Marketing Hub: Primarily consult and support updates of ForceBrand's marketing process and HubSpot functionality") -> HubSpot Implementation - Marketing Hub: Primarily consult and support updates of ForceBrand's marketing process and HubSpot functionality | G40: =IFERROR(__xludf.DUMMYFUNCTION("""COMPUTED_VALUE"""),36.0) -> 36 | H40: =G40*C11 -> 8532
B41: =IFERROR(__xludf.DUMMYFUNCTION("""COMPUTED_VALUE"""),"Project Management") -> Project Management | C41: =IFERROR(__xludf.DUMMYFUNCTION("""COMPUTED_VALUE"""),104.0) -> 104 | D41: =C41/$C$45 -> 0.18621307 | F41: =IFERROR(__xludf.DUMMYFUNCTION("""COMPUTED_VALUE"""),"HubSpot Implementation - Sales Hub: Implement HubSpot Sales Hub that aligns with ForceBrands's processes and data needs. ") -> HubSpot Implementation - Sales Hub: Implement HubSpot Sales Hub that aligns with ForceBrands's processes and data needs. | G41: =IFERROR(__xludf.DUMMYFUNCTION("""COMPUTED_VALUE"""),41.0) -> 41 | H41: =G41*C11 -> 9717
B42: =IFERROR(__xludf.DUMMYFUNCTION("""COMPUTED_VALUE"""),"Solutions Engineering") -> Solutions Engineering | C42: =IFERROR(__xludf.DUMMYFUNCTION("""COMPUTED_VALUE"""),164.0) -> 164 | D42: =C42/$C$45 -> 0.29364369 | F42: =IFERROR(__xludf.DUMMYFUNCTION("""COMPUTED_VALUE"""),"HubSpot Consulting - Content Hub: Support the holistic project with website consulting to ForceBrands and additional vendor") -> HubSpot Consulting - Content Hub: Support the holistic project with website consulting to ForceBrands and additional vendor | G42: =IFERROR(__xludf.DUMMYFUNCTION("""COMPUTED_VALUE"""),10.0) -> 10 | H42: =G42*C11 -> 2370
B43: =IFERROR(__xludf.DUMMYFUNCTION("""COMPUTED_VALUE"""),"Strategy") -> Strategy | C43: =IFERROR(__xludf.DUMMYFUNCTION("""COMPUTED_VALUE"""),53.5) -> 53.5 | D43: =C43/$C$45 -> 0.095792301 | F43: =IFERROR(__xludf.DUMMYFUNCTION("""COMPUTED_VALUE"""),"Data Migration: Migrate Bullhorn entity / object data into HubSpot to support lead and account management") -> Data Migration: Migrate Bullhorn entity / object data into HubSpot to support lead and account management | G43: =IFERROR(__xludf.DUMMYFUNCTION("""COMPUTED_VALUE"""),32.0) -> 32 | H43: =G43*C11 -> 7584
B44: =IFERROR(__xludf.DUMMYFUNCTION("""COMPUTED_VALUE"""),"Unassigned") -> Unassigned | C44: =IFERROR(__xludf.DUMMYFUNCTION("""COMPUTED_VALUE"""),0.0) -> 0 | D44: =C44/$C$45 -> 0 | F44: =IFERROR(__xludf.DUMMYFUNCTION("""COMPUTED_VALUE"""),"Bullhorn ATS <> HubSpot System Integration: Develop a custom data connector between Bullhorn and HubSpot") -> Bullhorn ATS <> HubSpot System Integration: Develop a custom data connector between Bullhorn and HubSpot | G44: =IFERROR(__xludf.DUMMYFUNCTION("""COMPUTED_VALUE"""),189.0) -> 189 | H44: =G44*C11 -> 44793
B45: Sum of Function-Based Hours | C45: =sum(C39:C44) -> 558.5 | D45: =SUM(D39:D44) -> 1 | F45: =IFERROR(__xludf.DUMMYFUNCTION("""COMPUTED_VALUE"""),"Sales + Marketing Reporting: Train ForceBrands on how to create custom reports and dashboards to support business insights directly in HubSpot") -> Sales + Marketing Reporting: Train ForceBrands on how to create custom reports and dashboards to support business insights directly in HubSpot | G45: =IFERROR(__xludf.DUMMYFUNCTION("""COMPUTED_VALUE"""),12.0) -> 12 | H45: =G45*C11 -> 2844
F46: =IFERROR(__xludf.DUMMYFUNCTION("""COMPUTED_VALUE"""),"Training & Documentation: Train ForceBrands resources on HubSpot best practices, contextual to their sales and marketing processes") -> Training & Documentation: Train ForceBrands resources on HubSpot best practices, contextual to their sales and marketing processes | G46: =IFERROR(__xludf.DUMMYFUNCTION("""COMPUTED_VALUE"""),29.0) -> 29 | H46: =G46*C11 -> 6873
...

Sheet Section
B1: New Section Template Note: Please do not edit rows 4 to 8, or change any volume of columns or it will break the script that pulls this content into the overview doc.
A4: • | B4: Generic Section: Summary about the delivery item | F4: =IFERROR(__xludf.DUMMYFUNCTION("ROUNDUP( ( SUM( INDIRECT( ""F""&(ROW()+1)&"":F""& IFERROR( INDEX( FILTER( ROW(A:A), REGEXMATCH(A:A, ""^[•◆■※⊳]""), ROW(A:A) > ROW() ), 1 "&" )-1, 999 ) ) )+ SUM( INDIRECT( ""G""&(ROW()+1)&"":G""& IFERROR( INDEX( FILTER( ROW(A:A), REGEXMATCH(A:A, ""^[•◆■※⊳]""), ROW(A:A) "&"> ROW() ), 1 )-1, 999 ) ) ) )/2 )"),23.0) -> 23 | H4: Low
B5: Lorem Ipsum | C5: Lorem Ipsum | D5: Lorem Ipsum | E5: Lorem Ipsum | F5: 5 | G5: 10
B6: Lorem Ipsum | C6: Lorem Ipsum | D6: Lorem Ipsum | E6: Lorem Ipsum | F6: 5 | G6: 10
B7: Lorem Ipsum | C7: Lorem Ipsum | D7: Lorem Ipsum | E7: Lorem Ipsum | F7: 5 | G7: 10
A12: ⊳ | B12: Generic: Summary about the delivery item | F12: =IFERROR(__xludf.DUMMYFUNCTION("ROUNDUP( ( SUM( INDIRECT( ""F""&(ROW()+1)&"":F""& IFERROR( INDEX( FILTER( ROW(A:A), REGEXMATCH(A:A, ""^[•◆■※⊳]""), ROW(A:A) > ROW() ), 1 "&" )-1, 999 ) ) )+ SUM( INDIRECT( ""G""&(ROW()+1)&"":G""& IFERROR( INDEX( FILTER( ROW(A:A), REGEXMATCH(A:A, ""^[•◆■※⊳]""), ROW(A:A) "&"> ROW() ), 1 )-1, 999 ) ) ) )/2 )"),30.0) -> 30 | H12: Low
B13: Lorem Ipsum | C13: Lorem Ipsum | D13: Lorem Ipsum | E13: Lorem Ipsum | F13: 10 | G13: 10
B14: Lorem Ipsum | C14: Lorem Ipsum | D14: Lorem Ipsum | E14: Lorem Ipsum | F14: 10 | G14: 10
B15: Lorem Ipsum | C15: Lorem Ipsum | D15: Lorem Ipsum | E15: Lorem Ipsum | F15: 10 | G15: 10
